Workbook

Sheet Faltantes Fevereiro- Metalfisa
B2: Data De Entrega dos Materiais | C2: 46057 | D2: 46059 | E2: 46066 | F2: 46073 | G2: 46081 | M2: ORDEM DE COMPRA | AU2: MESA 7560 | AV2: MESA 100100 | AW2: MESA 100100 H | AX2: TECLADO OPERAÇÃO ELET. NOVA | AY2: BODYSCAN HSV | AZ2: BODYSCAN DV | BA2: SPEC 5333 | BB2: SPEC 5536 | BC2: SPEC 6040 C | BD2: SPEC 6040 C TRIF | BE2: SPEC 6040 C ELET. NOVA | BF2: SPEC 6040 SV | BG2: SPEC 6040 P3D | BH2: SPEC 6040 DV | BI2: SPEC 7560 | BJ2: SPEC 100100 M | BK2: SPEC 100100 DV | BL2: SPEC 100100 HDV | BM2: FLATSCAN | BN2: SPEC 180180 SV 200KV | BO2: SPEC 180180 DV 320KV | BP2: SPEC CARGO | BQ2: PHANTOM COLORIZAÇÃO CARGO | BR2: PHANTOM 180180 200KV | BS2: RECYCLING INOX | BT2: RECYCLING INOX C | BU2: CARGO GANTRY | BV2: SPEC 6550 VMI | BW2: SPEC 6040 C 180KV | BX2: SPEC 6040 SV 180KV | BY2: SPEC 6040 DV 180KV | BZ2: SPEC 6040 P3D 180KV | CA2: PORTAL GARRETT | CB2: ARCO DE LEITURA | CC2: TECLADO ELET. NOVA | CD2: MESA 6040 DV INFRAERO | CE2: CABINE BS | CF2: BASE 5333 | CG2: MESA 5333 | CH2: MESA 5536/6040 | CI2: MESA 6040 C | CJ2: MESA 7560 | CK2: PEDESTAL 1 MONITOR | CL2: PEDESTAL 2 MONITORES
A3: CÓDIGO | B3: DESCRIÇÃO | C3: WK 01 | D3: WK 02 | E3: WK 03 | F3: WK 04 | G3: WK 05 | H3: FALTANTES FIRMES | I3: ENTRADAS | J3: ESTQ.S/OC | K3: FOLLOW-UP | L3: OC'S METALFISA | M3: 036137 | N3: 036605 | O3: 036620 | P3: 036622 | Q3: 037335 | R3: 037485 | S3: 037634 | T3: 038053 | U3: 046695 | V3: 046755 | W3: 047542 | X3: 047809 | Y3: 047973 | Z3: 048098 | AA3: 048653 | AB3: 048978 | AC3: 049117 | AD3: 049151 | AE3: 049278 | AF3: 049541 | AG3: 049636 | AH3: 049818 | AI3: 049826 | AJ3: 049835 | AK3: 052204 | AL3: 052728 | AM3: 052814 | AN3: 049826 | AO3: 049835 | AP3: 051062
A4: 13.01.00054 | B4: DMC 457 - FIXACAO LAMPADA 02 \ AA_0457_02 | C4: 0 | D4: 0 | E4: 0 | F4: 0 | G4: 6 | H4: =IFERROR(VLOOKUP(A4,[1]FALTANTES!$A:$AB,28,FALSE),"-") -> 0 | I4: =IFERROR(VLOOKUP(A4,[1]FALTANTES!$A:$AC,29,FALSE),"-") -> 0 | J4: =IFERROR(VLOOKUP(A4,[1]FALTANTES!$A:$AD,30,FALSE),"-") -> -6 | K4: 0 | L4: =SUM(M4:AS4) -> 6 | M4: =SUMIFS(METALFISA!$E:$E,METALFISA!$A:$A,'Faltantes Fevereiro- Metalfisa'!M$3,METALFISA!$B:$B,'Faltantes Fevereiro- Metalfisa'!$A4) -> 0 | N4: =SUMIFS(METALFISA!$E:$E,METALFISA!$A:$A,'Faltantes Fevereiro- Metalfisa'!N$3,METALFISA!$B:$B,'Faltantes Fevereiro- Metalfisa'!$A4) -> 0 | O4: =SUMIFS(METALFISA!$E:$E,METALFISA!$A:$A,'Faltantes Fevereiro- Metalfisa'!O$3,METALFISA!$B:$B,'Faltantes Fevereiro- Metalfisa'!$A4) -> 0 | P4: =SUMIFS(METALFISA!$E:$E,METALFISA!$A:$A,'Faltantes Fevereiro- Metalfisa'!P$3,METALFISA!$B:$B,'Faltantes Fevereiro- Metalfisa'!$A4) -> 0 | Q4: =SUMIFS(METALFISA!$E:$E,METALFISA!$A:$A,'Faltantes Fevereiro- Metalfisa'!Q$3,METALFISA!$B:$B,'Faltantes Fevereiro- Metalfisa'!$A4) -> 0 | R4: =SUMIFS(METALFISA!$E:$E,METALFISA!$A:$A,'Faltantes Fevereiro- Metalfisa'!R$3,METALFISA!$B:$B,'Faltantes Fevereiro- Metalfisa'!$A4) -> 0 | S4: =SUMIFS(METALFISA!$E:$E,METALFISA!$A:$A,'Faltantes Fevereiro- Metalfisa'!S$3,METALFISA!$B:$B,'Faltantes Fevereiro- Metalfisa'!$A4) -> 0 | T4: =SUMIFS(METALFISA!$E:$E,METALFISA!$A:$A,'Faltantes Fevereiro- Metalfisa'!T$3,METALFISA!$B:$B,'Faltantes Fevereiro- Metalfisa'!$A4) -> 0 | ... AP4: =SUMIFS(METALFISA!$E:$E,METALFISA!$A:$A,'Faltantes Fevereiro- Metalfisa'!AP$3,METALFISA!$B:$B,'Faltantes Fevereiro- Metalfisa'!$A4) -> 0 | AR4: =SUMIFS(METALFISA!$E:$E,METALFISA!$A:$A,'Faltantes Fevereiro- Metalfisa'!AR$3,METALFISA!$B:$B,'Faltantes Fevereiro- Metalfisa'!$A4) -> 0 | AS4: =SUMIFS(METALFISA!$E:$E,METALFISA!$A:$A,'Faltantes Fevereiro- Metalfisa'!AS$3,METALFISA!$B:$B,'Faltantes Fevereiro- Metalfisa'!$A4) -> 0 | AU4: 0 | AV4: 0 | AW4: 0 | AX4: 0 | AY4: 0 | AZ4: 0 | BA4: 0 | BB4: 0 | BC4: 0 | BD4: 0 | BE4: 0 | BF4: 0 | BG4: 0 | BH4: 0 | BI4: 0 | BJ4: 0 | BK4: 0 | BL4: 0 | BM4: 2 | BN4: 0 | BO4: 0 | BP4: 0 | BQ4: 0 | BR4: 0 | BS4: 0 | BT4: 0 | BU4: 0 | BV4: 0 | BW4: 0 | BX4: 0 | BY4: 0 | BZ4: 0 | CA4: 0 | CB4: 0 | CC4: 0 | CD4: 0 | CE4: 0 | CF4: 0 | CG4: 0 | CH4: 0 | CI4: 0 | CJ4: 0 | CK4: 0 | CL4: 0
A5: 13.03.00005 | B5: APOIO DO TECLADO / AA_0196_10 | C5: 0 | D5: 0 | E5: 0 | F5: 0 | G5: 2 | H5: =IFERROR(VLOOKUP(A5,[1]FALTANTES!$A:$AB,28,FALSE),"-") -> 0 | I5: =IFERROR(VLOOKUP(A5,[1]FALTANTES!$A:$AC,29,FALSE),"-") -> 0 | J5: =IFERROR(VLOOKUP(A5,[1]FALTANTES!$A:$AD,30,FALSE),"-") -> -2 | K5: 0 | L5: =SUM(M5:AS5) -> 2 | M5: =SUMIFS(METALFISA!$E:$E,METALFISA!$A:$A,'Faltantes Fevereiro- Metalfisa'!M$3,METALFISA!$B:$B,'Faltantes Fevereiro- Metalfisa'!$A5) -> 0 | N5: =SUMIFS(METALFISA!$E:$E,METALFISA!$A:$A,'Faltantes Fevereiro- Metalfisa'!N$3,METALFISA!$B:$B,'Faltantes Fevereiro- Metalfisa'!$A5) -> 0 | O5: =SUMIFS(METALFISA!$E:$E,METALFISA!$A:$A,'Faltantes Fevereiro- Metalfisa'!O$3,METALFISA!$B:$B,'Faltantes Fevereiro- Metalfisa'!$A5) -> 0 | P5: =SUMIFS(METALFISA!$E:$E,METALFISA!$A:$A,'Faltantes Fevereiro- Metalfisa'!P$3,METALFISA!$B:$B,'Faltantes Fevereiro- Metalfisa'!$A5) -> 0 | Q5: =SUMIFS(METALFISA!$E:$E,METALFISA!$A:$A,'Faltantes Fevereiro- Metalfisa'!Q$3,METALFISA!$B:$B,'Faltantes Fevereiro- Metalfisa'!$A5) -> 0 | R5: =SUMIFS(METALFISA!$E:$E,METALFISA!$A:$A,'Faltantes Fevereiro- Metalfisa'!R$3,METALFISA!$B:$B,'Faltantes Fevereiro- Metalfisa'!$A5) -> 0 | S5: =SUMIFS(METALFISA!$E:$E,METALFISA!$A:$A,'Faltantes Fevereiro- Metalfisa'!S$3,METALFISA!$B:$B,'Faltantes Fevereiro- Metalfisa'!$A5) -> 0 | T5: =SUMIFS(METALFISA!$E:$E,METALFISA!$A:$A,'Faltantes Fevereiro- Metalfisa'!T$3,METALFISA!$B:$B,'Faltantes Fevereiro- Metalfisa'!$A5) -> 0 | ... AP5: =SUMIFS(METALFISA!$E:$E,METALFISA!$A:$A,'Faltantes Fevereiro- Metalfisa'!AP$3,METALFISA!$B:$B,'Faltantes Fevereiro- Metalfisa'!$A5) -> 0 | AR5: =SUMIFS(METALFISA!$E:$E,METALFISA!$A:$A,'Faltantes Fevereiro- Metalfisa'!AR$3,METALFISA!$B:$B,'Faltantes Fevereiro- Metalfisa'!$A5) -> 0 | AS5: =SUMIFS(METALFISA!$E:$E,METALFISA!$A:$A,'Faltantes Fevereiro- Metalfisa'!AS$3,METALFISA!$B:$B,'Faltantes Fevereiro- Metalfisa'!$A5) -> 0 | AU5: 0 | AV5: 0 | AW5: 0 | AX5: 0 | AY5: 0 | AZ5: 0 | BA5: 0 | BB5: 0 | BC5: 0 | BD5: 0 | BE5: 0 | BF5: 0 | BG5: 0 | BH5: 0 | BI5: 0 | BJ5: 0 | BK5: 0 | BL5: 0 | BM5: 1 | BN5: 0 | BO5: 0 | BP5: 0 | BQ5: 0 | BR5: 0 | BS5: 0 | BT5: 0 | BU5: 0 | BV5: 0 | BW5: 0 | BX5: 0 | BY5: 0 | BZ5: 0 | CA5: 0 | CB5: 0 | CC5: 0 | CD5: 0 | CE5: 0 | CF5: 0 | CG5: 0 | CH5: 0 | CI5: 0 | CJ5: 0 | CK5: 0 | CL5: 0
A6: 13.03.00055 | B6: PERFIL SUPERIOR ESTRUTURA / AA_0373_05 | C6: 0 | D6: 0 | E6: 0 | F6: 0 | G6: 6 | H6: =IFERROR(VLOOKUP(A6,[1]FALTANTES!$A:$AB,28,FALSE),"-") -> 0 | I6: =IFERROR(VLOOKUP(A6,[1]FALTANTES!$A:$AC,29,FALSE),"-") -> 0 | J6: =IFERROR(VLOOKUP(A6,[1]FALTANTES!$A:$AD,30,FALSE),"-") -> -6 | K6: 0 | L6: =SUM(M6:AS6) -> 6 | M6: =SUMIFS(METALFISA!$E:$E,METALFISA!$A:$A,'Faltantes Fevereiro- Metalfisa'!M$3,METALFISA!$B:$B,'Faltantes Fevereiro- Metalfisa'!$A6) -> 0 | N6: =SUMIFS(METALFISA!$E:$E,METALFISA!$A:$A,'Faltantes Fevereiro- Metalfisa'!N$3,METALFISA!$B:$B,'Faltantes Fevereiro- Metalfisa'!$A6) -> 0 | O6: =SUMIFS(METALFISA!$E:$E,METALFISA!$A:$A,'Faltantes Fevereiro- Metalfisa'!O$3,METALFISA!$B:$B,'Faltantes Fevereiro- Metalfisa'!$A6) -> 0 | P6: =SUMIFS(METALFISA!$E:$E,METALFISA!$A:$A,'Faltantes Fevereiro- Metalfisa'!P$3,METALFISA!$B:$B,'Faltantes Fevereiro- Metalfisa'!$A6) -> 0 | Q6: =SUMIFS(METALFISA!$E:$E,METALFISA!$A:$A,'Faltantes Fevereiro- Metalfisa'!Q$3,METALFISA!$B:$B,'Faltantes Fevereiro- Metalfisa'!$A6) -> 0 | R6: =SUMIFS(METALFISA!$E:$E,METALFISA!$A:$A,'Faltantes Fevereiro- Metalfisa'!R$3,METALFISA!$B:$B,'Faltantes Fevereiro- Metalfisa'!$A6) -> 0 | S6: =SUMIFS(METALFISA!$E:$E,METALFISA!$A:$A,'Faltantes Fevereiro- Metalfisa'!S$3,METALFISA!$B:$B,'Faltantes Fevereiro- Metalfisa'!$A6) -> 0 | T6: =SUMIFS(METALFISA!$E:$E,METALFISA!$A:$A,'Faltantes Fevereiro- Metalfisa'!T$3,METALFISA!$B:$B,'Faltantes Fevereiro- Metalfisa'!$A6) -> 0 | ... AP6: =SUMIFS(METALFISA!$E:$E,METALFISA!$A:$A,'Faltantes Fevereiro- Metalfisa'!AP$3,METALFISA!$B:$B,'Faltantes Fevereiro- Metalfisa'!$A6) -> 0 | AR6: =SUMIFS(METALFISA!$E:$E,METALFISA!$A:$A,'Faltantes Fevereiro- Metalfisa'!AR$3,METALFISA!$B:$B,'Faltantes Fevereiro- Metalfisa'!$A6) -> 0 | AS6: =SUMIFS(METALFISA!$E:$E,METALFISA!$A:$A,'Faltantes Fevereiro- Metalfisa'!AS$3,METALFISA!$B:$B,'Faltantes Fevereiro- Metalfisa'!$A6) -> 0 | AU6: 0 | AV6: 0 | AW6: 0 | AX6: 0 | AY6: 0 | AZ6: 0 | BA6: 0 | BB6: 0 | BC6: 0 | BD6: 0 | BE6: 0 | BF6: 0 | BG6: 0 | BH6: 0 | BI6: 0 | BJ6: 0 | BK6: 0 | BL6: 0 | BM6: 2 | BN6: 0 | BO6: 0 | BP6: 0 | BQ6: 0 | BR6: 0 | BS6: 0 | BT6: 0 | BU6: 0 | BV6: 0 | BW6: 0 | BX6: 0 | BY6: 0 | BZ6: 0 | CA6: 0 | CB6: 0 | CC6: 0 | CD6: 0 | CE6: 0 | CF6: 0 | CG6: 0 | CH6: 0 | CI6: 0 | CJ6: 0 | CK6: 0 | CL6: 0
A7: 13.03.00056 | B7: PERFIL SUPERIOR COM AFASTADOR / AA_0374_07 | C7: 0 | D7: 0 | E7: 0 | F7: 0 | G7: 6 | H7: =IFERROR(VLOOKUP(A7,[1]FALTANTES!$A:$AB,28,FALSE),"-") -> 0 | I7: =IFERROR(VLOOKUP(A7,[1]FALTANTES!$A:$AC,29,FALSE),"-") -> 0 | J7: =IFERROR(VLOOKUP(A7,[1]FALTANTES!$A:$AD,30,FALSE),"-") -> -6 | K7: 0 | L7: =SUM(M7:AS7) -> 6 | M7: =SUMIFS(METALFISA!$E:$E,METALFISA!$A:$A,'Faltantes Fevereiro- Metalfisa'!M$3,METALFISA!$B:$B,'Faltantes Fevereiro- Metalfisa'!$A7) -> 0 | N7: =SUMIFS(METALFISA!$E:$E,METALFISA!$A:$A,'Faltantes Fevereiro- Metalfisa'!N$3,METALFISA!$B:$B,'Faltantes Fevereiro- Metalfisa'!$A7) -> 0 | O7: =SUMIFS(METALFISA!$E:$E,METALFISA!$A:$A,'Faltantes Fevereiro- Metalfisa'!O$3,METALFISA!$B:$B,'Faltantes Fevereiro- Metalfisa'!$A7) -> 0 | P7: =SUMIFS(METALFISA!$E:$E,METALFISA!$A:$A,'Faltantes Fevereiro- Metalfisa'!P$3,METALFISA!$B:$B,'Faltantes Fevereiro- Metalfisa'!$A7) -> 0 | Q7: =SUMIFS(METALFISA!$E:$E,METALFISA!$A:$A,'Faltantes Fevereiro- Metalfisa'!Q$3,METALFISA!$B:$B,'Faltantes Fevereiro- Metalfisa'!$A7) -> 0 | R7: =SUMIFS(METALFISA!$E:$E,METALFISA!$A:$A,'Faltantes Fevereiro- Metalfisa'!R$3,METALFISA!$B:$B,'Faltantes Fevereiro- Metalfisa'!$A7) -> 0 | S7: =SUMIFS(METALFISA!$E:$E,METALFISA!$A:$A,'Faltantes Fevereiro- Metalfisa'!S$3,METALFISA!$B:$B,'Faltantes Fevereiro- Metalfisa'!$A7) -> 0 | T7: =SUMIFS(METALFISA!$E:$E,METALFISA!$A:$A,'Faltantes Fevereiro- Metalfisa'!T$3,METALFISA!$B:$B,'Faltantes Fevereiro- Metalfisa'!$A7) -> 0 | ... AP7: =SUMIFS(METALFISA!$E:$E,METALFISA!$A:$A,'Faltantes Fevereiro- Metalfisa'!AP$3,METALFISA!$B:$B,'Faltantes Fevereiro- Metalfisa'!$A7) -> 0 | AR7: =SUMIFS(METALFISA!$E:$E,METALFISA!$A:$A,'Faltantes Fevereiro- Metalfisa'!AR$3,METALFISA!$B:$B,'Faltantes Fevereiro- Metalfisa'!$A7) -> 0 | AS7: =SUMIFS(METALFISA!$E:$E,METALFISA!$A:$A,'Faltantes Fevereiro- Metalfisa'!AS$3,METALFISA!$B:$B,'Faltantes Fevereiro- Metalfisa'!$A7) -> 0 | AU7: 0 | AV7: 0 | AW7: 0 | AX7: 0 | AY7: 0 | AZ7: 0 | BA7: 0 | BB7: 0 | BC7: 0 | BD7: 0 | BE7: 0 | BF7: 0 | BG7: 0 | BH7: 0 | BI7: 0 | BJ7: 0 | BK7: 0 | BL7: 0 | BM7: 2 | BN7: 0 | BO7: 0 | BP7: 0 | BQ7: 0 | BR7: 0 | BS7: 0 | BT7: 0 | BU7: 0 | BV7: 0 | BW7: 0 | BX7: 0 | BY7: 0 | BZ7: 0 | CA7: 0 | CB7: 0 | CC7: 0 | CD7: 0 | CE7: 0 | CF7: 0 | CG7: 0 | CH7: 0 | CI7: 0 | CJ7: 0 | CK7: 0 | CL7: 0
A8: 13.03.00057 | B8: DMC-376 - METALON SUPERIOR \ AA_0376_05 | C8: 0 | D8: 0 | E8: 0 | F8: 0 | G8: 4 | H8: =IFERROR(VLOOKUP(A8,[1]FALTANTES!$A:$AB,28,FALSE),"-") -> 0 | I8: =IFERROR(VLOOKUP(A8,[1]FALTANTES!$A:$AC,29,FALSE),"-") -> 2 | J8: =IFERROR(VLOOKUP(A8,[1]FALTANTES!$A:$AD,30,FALSE),"-") -> -2 | K8: 0 | L8: =SUM(M8:AS8) -> 2 | M8: =SUMIFS(METALFISA!$E:$E,METALFISA!$A:$A,'Faltantes Fevereiro- Metalfisa'!M$3,METALFISA!$B:$B,'Faltantes Fevereiro- Metalfisa'!$A8) -> 0 | N8: =SUMIFS(METALFISA!$E:$E,METALFISA!$A:$A,'Faltantes Fevereiro- Metalfisa'!N$3,METALFISA!$B:$B,'Faltantes Fevereiro- Metalfisa'!$A8) -> 0 | O8: =SUMIFS(METALFISA!$E:$E,METALFISA!$A:$A,'Faltantes Fevereiro- Metalfisa'!O$3,METALFISA!$B:$B,'Faltantes Fevereiro- Metalfisa'!$A8) -> 0 | P8: =SUMIFS(METALFISA!$E:$E,METALFISA!$A:$A,'Faltantes Fevereiro- Metalfisa'!P$3,METALFISA!$B:$B,'Faltantes Fevereiro- Metalfisa'!$A8) -> 0 | Q8: =SUMIFS(METALFISA!$E:$E,METALFISA!$A:$A,'Faltantes Fevereiro- Metalfisa'!Q$3,METALFISA!$B:$B,'Faltantes Fevereiro- Metalfisa'!$A8) -> 0 | R8: =SUMIFS(METALFISA!$E:$E,METALFISA!$A:$A,'Faltantes Fevereiro- Metalfisa'!R$3,METALFISA!$B:$B,'Faltantes Fevereiro- Metalfisa'!$A8) -> 0 | S8: =SUMIFS(METALFISA!$E:$E,METALFISA!$A:$A,'Faltantes Fevereiro- Metalfisa'!S$3,METALFISA!$B:$B,'Faltantes Fevereiro- Metalfisa'!$A8) -> 0 | T8: =SUMIFS(METALFISA!$E:$E,METALFISA!$A:$A,'Faltantes Fevereiro- Metalfisa'!T$3,METALFISA!$B:$B,'Faltantes Fevereiro- Metalfisa'!$A8) -> 0 | ... AP8: =SUMIFS(METALFISA!$E:$E,METALFISA!$A:$A,'Faltantes Fevereiro- Metalfisa'!AP$3,METALFISA!$B:$B,'Faltantes Fevereiro- Metalfisa'!$A8) -> 0 | AR8: =SUMIFS(METALFISA!$E:$E,METALFISA!$A:$A,'Faltantes Fevereiro- Metalfisa'!AR$3,METALFISA!$B:$B,'Faltantes Fevereiro- Metalfisa'!$A8) -> 0 | AS8: =SUMIFS(METALFISA!$E:$E,METALFISA!$A:$A,'Faltantes Fevereiro- Metalfisa'!AS$3,METALFISA!$B:$B,'Faltantes Fevereiro- Metalfisa'!$A8) -> 0 | AU8: 0 | AV8: 0 | AW8: 0 | AX8: 0 | AY8: 0 | AZ8: 0 | BA8: 0 | BB8: 0 | BC8: 0 | BD8: 0 | BE8: 0 | BF8: 0 | BG8: 0 | BH8: 0 | BI8: 0 | BJ8: 0 | BK8: 0 | BL8: 0 | BM8: 2 | BN8: 0 | BO8: 0 | BP8: 0 | BQ8: 0 | BR8: 0 | BS8: 0 | BT8: 0 | BU8: 0 | BV8: 0 | BW8: 0 | BX8: 0 | BY8: 0 | BZ8: 0 | CA8: 0 | CB8: 0 | CC8: 0 | CD8: 0 | CE8: 0 | CF8: 0 | CG8: 0 | CH8: 0 | CI8: 0 | CJ8: 0 | CK8: 0 | CL8: 0
A9: 13.03.00059 | B9: DMC-384 - REGULADOR TAMPAS EXTERNAS \ AA_0384_01 | C9: 0 | D9: 0 | E9: 0 | F9: 0 | G9: 8 | H9: =IFERROR(VLOOKUP(A9,[1]FALTANTES!$A:$AB,28,FALSE),"-") -> 0 | I9: =IFERROR(VLOOKUP(A9,[1]FALTANTES!$A:$AC,29,FALSE),"-") -> 0 | J9: =IFERROR(VLOOKUP(A9,[1]FALTANTES!$A:$AD,30,FALSE),"-") -> -8 | K9: 0 | L9: =SUM(M9:AS9) -> 8 | M9: =SUMIFS(METALFISA!$E:$E,METALFISA!$A:$A,'Faltantes Fevereiro- Metalfisa'!M$3,METALFISA!$B:$B,'Faltantes Fevereiro- Metalfisa'!$A9) -> 0 | N9: =SUMIFS(METALFISA!$E:$E,METALFISA!$A:$A,'Faltantes Fevereiro- Metalfisa'!N$3,METALFISA!$B:$B,'Faltantes Fevereiro- Metalfisa'!$A9) -> 0 | O9: =SUMIFS(METALFISA!$E:$E,METALFISA!$A:$A,'Faltantes Fevereiro- Metalfisa'!O$3,METALFISA!$B:$B,'Faltantes Fevereiro- Metalfisa'!$A9) -> 0 | P9: =SUMIFS(METALFISA!$E:$E,METALFISA!$A:$A,'Faltantes Fevereiro- Metalfisa'!P$3,METALFISA!$B:$B,'Faltantes Fevereiro- Metalfisa'!$A9) -> 0 | Q9: =SUMIFS(METALFISA!$E:$E,METALFISA!$A:$A,'Faltantes Fevereiro- Metalfisa'!Q$3,METALFISA!$B:$B,'Faltantes Fevereiro- Metalfisa'!$A9) -> 0 | R9: =SUMIFS(METALFISA!$E:$E,METALFISA!$A:$A,'Faltantes Fevereiro- Metalfisa'!R$3,METALFISA!$B:$B,'Faltantes Fevereiro- Metalfisa'!$A9) -> 0 | S9: =SUMIFS(METALFISA!$E:$E,METALFISA!$A:$A,'Faltantes Fevereiro- Metalfisa'!S$3,METALFISA!$B:$B,'Faltantes Fevereiro- Metalfisa'!$A9) -> 0 | T9: =SUMIFS(METALFISA!$E:$E,METALFISA!$A:$A,'Faltantes Fevereiro- Metalfisa'!T$3,METALFISA!$B:$B,'Faltantes Fevereiro- Metalfisa'!$A9) -> 0 | ... AP9: =SUMIFS(METALFISA!$E:$E,METALFISA!$A:$A,'Faltantes Fevereiro- Metalfisa'!AP$3,METALFISA!$B:$B,'Faltantes Fevereiro- Metalfisa'!$A9) -> 0 | AR9: =SUMIFS(METALFISA!$E:$E,METALFISA!$A:$A,'Faltantes Fevereiro- Metalfisa'!AR$3,METALFISA!$B:$B,'Faltantes Fevereiro- Metalfisa'!$A9) -> 0 | AS9: =SUMIFS(METALFISA!$E:$E,METALFISA!$A:$A,'Faltantes Fevereiro- Metalfisa'!AS$3,METALFISA!$B:$B,'Faltantes Fevereiro- Metalfisa'!$A9) -> 0 | AU9: 0 | AV9: 0 | AW9: 0 | AX9: 0 | AY9: 0 | AZ9: 0 | BA9: 0 | BB9: 0 | BC9: 0 | BD9: 0 | BE9: 0 | BF9: 0 | BG9: 0 | BH9: 0 | BI9: 0 | BJ9: 0 | BK9: 0 | BL9: 0 | BM9: 4 | BN9: 0 | BO9: 0 | BP9: 0 | BQ9: 0 | BR9: 0 | BS9: 0 | BT9: 0 | BU9: 0 | BV9: 0 | BW9: 0 | BX9: 0 | BY9: 0 | BZ9: 0 | CA9: 0 | CB9: 0 | CC9: 0 | CD9: 0 | CE9: 0 | CF9: 0 | CG9: 0 | CH9: 0 | CI9: 0 | CJ9: 0 | CK9: 0 | CL9: 0
A10: 13.03.00062 | B10: BANDEJA SUPORTE CPU / AA_0394_08 | C10: 0 | D10: 0 | E10: 0 | F10: 0 | G10: 3 | H10: =IFERROR(VLOOKUP(A10,[1]FALTANTES!$A:$AB,28,FALSE),"-") -> 0 | I10: =IFERROR(VLOOKUP(A10,[1]FALTANTES!$A:$AC,29,FALSE),"-") -> 0 | J10: =IFERROR(VLOOKUP(A10,[1]FALTANTES!$A:$AD,30,FALSE),"-") -> -3 | K10: 0 | L10: =SUM(M10:AS10) -> 3 | M10: =SUMIFS(METALFISA!$E:$E,METALFISA!$A:$A,'Faltantes Fevereiro- Metalfisa'!M$3,METALFISA!$B:$B,'Faltantes Fevereiro- Metalfisa'!$A10) -> 0 | N10: =SUMIFS(METALFISA!$E:$E,METALFISA!$A:$A,'Faltantes Fevereiro- Metalfisa'!N$3,METALFISA!$B:$B,'Faltantes Fevereiro- Metalfisa'!$A10) -> 0 | O10: =SUMIFS(METALFISA!$E:$E,METALFISA!$A:$A,'Faltantes Fevereiro- Metalfisa'!O$3,METALFISA!$B:$B,'Faltantes Fevereiro- Metalfisa'!$A10) -> 0 | P10: =SUMIFS(METALFISA!$E:$E,METALFISA!$A:$A,'Faltantes Fevereiro- Metalfisa'!P$3,METALFISA!$B:$B,'Faltantes Fevereiro- Metalfisa'!$A10) -> 0 | Q10: =SUMIFS(METALFISA!$E:$E,METALFISA!$A:$A,'Faltantes Fevereiro- Metalfisa'!Q$3,METALFISA!$B:$B,'Faltantes Fevereiro- Metalfisa'!$A10) -> 0 | R10: =SUMIFS(METALFISA!$E:$E,METALFISA!$A:$A,'Faltantes Fevereiro- Metalfisa'!R$3,METALFISA!$B:$B,'Faltantes Fevereiro- Metalfisa'!$A10) -> 0 | S10: =SUMIFS(METALFISA!$E:$E,METALFISA!$A:$A,'Faltantes Fevereiro- Metalfisa'!S$3,METALFISA!$B:$B,'Faltantes Fevereiro- Metalfisa'!$A10) -> 0 | T10: =SUMIFS(METALFISA!$E:$E,METALFISA!$A:$A,'Faltantes Fevereiro- Metalfisa'!T$3,METALFISA!$B:$B,'Faltantes Fevereiro- Metalfisa'!$A10) -> 0 | ... AP10: =SUMIFS(METALFISA!$E:$E,METALFISA!$A:$A,'Faltantes Fevereiro- Metalfisa'!AP$3,METALFISA!$B:$B,'Faltantes Fevereiro- Metalfisa'!$A10) -> 0 | AR10: =SUMIFS(METALFISA!$E:$E,METALFISA!$A:$A,'Faltantes Fevereiro- Metalfisa'!AR$3,METALFISA!$B:$B,'Faltantes Fevereiro- Metalfisa'!$A10) -> 0 | AS10: =SUMIFS(METALFISA!$E:$E,METALFISA!$A:$A,'Faltantes Fevereiro- Metalfisa'!AS$3,METALFISA!$B:$B,'Faltantes Fevereiro- Metalfisa'!$A10) -> 0 | AU10: 0 | AV10: 0 | AW10: 0 | AX10: 0 | AY10: 0 | AZ10: 0 | BA10: 0 | BB10: 0 | BC10: 0 | BD10: 0 | BE10: 0 | BF10: 0 | BG10: 0 | BH10: 0 | BI10: 0 | BJ10: 0 | BK10: 0 | BL10: 0 | BM10: 1 | BN10: 0 | BO10: 0 | BP10: 0 | BQ10: 0 | BR10: 0 | BS10: 0 | BT10: 0 | BU10: 0 | BV10: 0 | BW10: 0 | BX10: 0 | BY10: 0 | BZ10: 0 | CA10: 0 | CB10: 0 | CC10: 0 | CD10: 0 | CE10: 0 | CF10: 0 | CG10: 0 | CH10: 0 | CI10: 0 | CJ10: 0 | CK10: 0 | CL10: 0
A11: 13.03.00065 | B11: DMC-400 - RAMPA COLIMADOR FLATSCAN \ AA_0400_00 | C11: 0 | D11: 0 | E11: 0 | F11: 0 | G11: 5 | H11: =IFERROR(VLOOKUP(A11,[1]FALTANTES!$A:$AB,28,FALSE),"-") -> 0 | I11: =IFERROR(VLOOKUP(A11,[1]FALTANTES!$A:$AC,29,FALSE),"-") -> 0 | J11: =IFERROR(VLOOKUP(A11,[1]FALTANTES!$A:$AD,30,FALSE),"-") -> -5 | K11: 0 | L11: =SUM(M11:AS11) -> 48 | M11: =SUMIFS(METALFISA!$E:$E,METALFISA!$A:$A,'Faltantes Fevereiro- Metalfisa'!M$3,METALFISA!$B:$B,'Faltantes Fevereiro- Metalfisa'!$A11) -> 0 | N11: =SUMIFS(METALFISA!$E:$E,METALFISA!$A:$A,'Faltantes Fevereiro- Metalfisa'!N$3,METALFISA!$B:$B,'Faltantes Fevereiro- Metalfisa'!$A11) -> 0 | O11: =SUMIFS(METALFISA!$E:$E,METALFISA!$A:$A,'Faltantes Fevereiro- Metalfisa'!O$3,METALFISA!$B:$B,'Faltantes Fevereiro- Metalfisa'!$A11) -> 0 | P11: =SUMIFS(METALFISA!$E:$E,METALFISA!$A:$A,'Faltantes Fevereiro- Metalfisa'!P$3,METALFISA!$B:$B,'Faltantes Fevereiro- Metalfisa'!$A11) -> 0 | Q11: =SUMIFS(METALFISA!$E:$E,METALFISA!$A:$A,'Faltantes Fevereiro- Metalfisa'!Q$3,METALFISA!$B:$B,'Faltantes Fevereiro- Metalfisa'!$A11) -> 0 | R11: =SUMIFS(METALFISA!$E:$E,METALFISA!$A:$A,'Faltantes Fevereiro- Metalfisa'!R$3,METALFISA!$B:$B,'Faltantes Fevereiro- Metalfisa'!$A11) -> 0 | S11: =SUMIFS(METALFISA!$E:$E,METALFISA!$A:$A,'Faltantes Fevereiro- Metalfisa'!S$3,METALFISA!$B:$B,'Faltantes Fevereiro- Metalfisa'!$A11) -> 0 | T11: =SUMIFS(METALFISA!$E:$E,METALFISA!$A:$A,'Faltantes Fevereiro- Metalfisa'!T$3,METALFISA!$B:$B,'Faltantes Fevereiro- Metalfisa'!$A11) -> 0 | ... AP11: =SUMIFS(METALFISA!$E:$E,METALFISA!$A:$A,'Faltantes Fevereiro- Metalfisa'!AP$3,METALFISA!$B:$B,'Faltantes Fevereiro- Metalfisa'!$A11) -> 0 | AR11: =SUMIFS(METALFISA!$E:$E,METALFISA!$A:$A,'Faltantes Fevereiro- Metalfisa'!AR$3,METALFISA!$B:$B,'Faltantes Fevereiro- Metalfisa'!$A11) -> 0 | AS11: =SUMIFS(METALFISA!$E:$E,METALFISA!$A:$A,'Faltantes Fevereiro- Metalfisa'!AS$3,METALFISA!$B:$B,'Faltantes Fevereiro- Metalfisa'!$A11) -> 0 | AU11: 0 | AV11: 0 | AW11: 0 | AX11: 0 | AY11: 0 | AZ11: 0 | BA11: 0 | BB11: 0 | BC11: 0 | BD11: 0 | BE11: 0 | BF11: 0 | BG11: 0 | BH11: 0 | BI11: 0 | BJ11: 0 | BK11: 0 | BL11: 0 | BM11: 16 | BN11: 0 | BO11: 0 | BP11: 0 | BQ11: 0 | BR11: 0 | BS11: 0 | BT11: 0 | BU11: 0 | BV11: 0 | BW11: 0 | BX11: 0 | BY11: 0 | BZ11: 0 | CA11: 0 | CB11: 0 | CC11: 0 | CD11: 0 | CE11: 0 | CF11: 0 | CG11: 0 | CH11: 0 | CI11: 0 | CJ11: 0 | CK11: 0 | CL11: 0
A12: 13.03.00080 | B12: DMC-273 - CHASSI PROT. MESA FLAT \ AA_0273_10 | C12: 0 | D12: 0 | E12: 0 | F12: 0 | G12: 4 | H12: =IFERROR(VLOOKUP(A12,[1]FALTANTES!$A:$AB,28,FALSE),"-") -> 0 | I12: =IFERROR(VLOOKUP(A12,[1]FALTANTES!$A:$AC,29,FALSE),"-") -> 2 | J12: =IFERROR(VLOOKUP(A12,[1]FALTANTES!$A:$AD,30,FALSE),"-") -> -2 | K12: ENTREGUE 2 PEÇAS NO DANFE 41640 EM 06/02-METALFISA | L12: =SUM(M12:AS12) -> 1 | M12: =SUMIFS(METALFISA!$E:$E,METALFISA!$A:$A,'Faltantes Fevereiro- Metalfisa'!M$3,METALFISA!$B:$B,'Faltantes Fevereiro- Metalfisa'!$A12) -> 0 | N12: =SUMIFS(METALFISA!$E:$E,METALFISA!$A:$A,'Faltantes Fevereiro- Metalfisa'!N$3,METALFISA!$B:$B,'Faltantes Fevereiro- Metalfisa'!$A12) -> 0 | O12: =SUMIFS(METALFISA!$E:$E,METALFISA!$A:$A,'Faltantes Fevereiro- Metalfisa'!O$3,METALFISA!$B:$B,'Faltantes Fevereiro- Metalfisa'!$A12) -> 0 | P12: =SUMIFS(METALFISA!$E:$E,METALFISA!$A:$A,'Faltantes Fevereiro- Metalfisa'!P$3,METALFISA!$B:$B,'Faltantes Fevereiro- Metalfisa'!$A12) -> 0 | Q12: =SUMIFS(METALFISA!$E:$E,METALFISA!$A:$A,'Faltantes Fevereiro- Metalfisa'!Q$3,METALFISA!$B:$B,'Faltantes Fevereiro- Metalfisa'!$A12) -> 0 | R12: =SUMIFS(METALFISA!$E:$E,METALFISA!$A:$A,'Faltantes Fevereiro- Metalfisa'!R$3,METALFISA!$B:$B,'Faltantes Fevereiro- Metalfisa'!$A12) -> 0 | S12: =SUMIFS(METALFISA!$E:$E,METALFISA!$A:$A,'Faltantes Fevereiro- Metalfisa'!S$3,METALFISA!$B:$B,'Faltantes Fevereiro- Metalfisa'!$A12) -> 0 | T12: =SUMIFS(METALFISA!$E:$E,METALFISA!$A:$A,'Faltantes Fevereiro- Metalfisa'!T$3,METALFISA!$B:$B,'Faltantes Fevereiro- Metalfisa'!$A12) -> 0 | ... AP12: =SUMIFS(METALFISA!$E:$E,METALFISA!$A:$A,'Faltantes Fevereiro- Metalfisa'!AP$3,METALFISA!$B:$B,'Faltantes Fevereiro- Metalfisa'!$A12) -> 0 | AR12: =SUMIFS(METALFISA!$E:$E,METALFISA!$A:$A,'Faltantes Fevereiro- Metalfisa'!AR$3,METALFISA!$B:$B,'Faltantes Fevereiro- Metalfisa'!$A12) -> 0 | AS12: =SUMIFS(METALFISA!$E:$E,METALFISA!$A:$A,'Faltantes Fevereiro- Metalfisa'!AS$3,METALFISA!$B:$B,'Faltantes Fevereiro- Metalfisa'!$A12) -> 0 | AU12: 0 | AV12: 0 | AW12: 0 | AX12: 0 | AY12: 0 | AZ12: 0 | BA12: 0 | BB12: 0 | BC12: 0 | BD12: 0 | BE12: 0 | BF12: 0 | BG12: 0 | BH12: 0 | BI12: 0 | BJ12: 0 | BK12: 0 | BL12: 0 | BM12: 1 | BN12: 0 | BO12: 0 | BP12: 0 | BQ12: 0 | BR12: 0 | BS12: 0 | BT12: 0 | BU12: 0 | BV12: 0 | BW12: 0 | BX12: 0 | BY12: 0 | BZ12: 0 | CA12: 0 | CB12: 0 | CC12: 0 | CD12: 0 | CE12: 0 | CF12: 0 | CG12: 0 | CH12: 0 | CI12: 0 | CJ12: 0 | CK12: 0 | CL12: 0
A13: 13.03.00081 | B13: DMC-275 - ACABAMENTO FLATSCAN \ AA_0275_05 | C13: 0 | D13: 0 | E13: 0 | F13: 0 | G13: 8 | H13: =IFERROR(VLOOKUP(A13,[1]FALTANTES!$A:$AB,28,FALSE),"-") -> 0 | I13: =IFERROR(VLOOKUP(A13,[1]FALTANTES!$A:$AC,29,FALSE),"-") -> 0 | J13: =IFERROR(VLOOKUP(A13,[1]FALTANTES!$A:$AD,30,FALSE),"-") -> -8 | K13: 0 | L13: =SUM(M13:AS13) -> 8 | M13: =SUMIFS(METALFISA!$E:$E,METALFISA!$A:$A,'Faltantes Fevereiro- Metalfisa'!M$3,METALFISA!$B:$B,'Faltantes Fevereiro- Metalfisa'!$A13) -> 0 | N13: =SUMIFS(METALFISA!$E:$E,METALFISA!$A:$A,'Faltantes Fevereiro- Metalfisa'!N$3,METALFISA!$B:$B,'Faltantes Fevereiro- Metalfisa'!$A13) -> 0 | O13: =SUMIFS(METALFISA!$E:$E,METALFISA!$A:$A,'Faltantes Fevereiro- Metalfisa'!O$3,METALFISA!$B:$B,'Faltantes Fevereiro- Metalfisa'!$A13) -> 0 | P13: =SUMIFS(METALFISA!$E:$E,METALFISA!$A:$A,'Faltantes Fevereiro- Metalfisa'!P$3,METALFISA!$B:$B,'Faltantes Fevereiro- Metalfisa'!$A13) -> 0 | Q13: =SUMIFS(METALFISA!$E:$E,METALFISA!$A:$A,'Faltantes Fevereiro- Metalfisa'!Q$3,METALFISA!$B:$B,'Faltantes Fevereiro- Metalfisa'!$A13) -> 0 | R13: =SUMIFS(METALFISA!$E:$E,METALFISA!$A:$A,'Faltantes Fevereiro- Metalfisa'!R$3,METALFISA!$B:$B,'Faltantes Fevereiro- Metalfisa'!$A13) -> 0 | S13: =SUMIFS(METALFISA!$E:$E,METALFISA!$A:$A,'Faltantes Fevereiro- Metalfisa'!S$3,METALFISA!$B:$B,'Faltantes Fevereiro- Metalfisa'!$A13) -> 0 | T13: =SUMIFS(METALFISA!$E:$E,METALFISA!$A:$A,'Faltantes Fevereiro- Metalfisa'!T$3,METALFISA!$B:$B,'Faltantes Fevereiro- Metalfisa'!$A13) -> 0 | ... AP13: =SUMIFS(METALFISA!$E:$E,METALFISA!$A:$A,'Faltantes Fevereiro- Metalfisa'!AP$3,METALFISA!$B:$B,'Faltantes Fevereiro- Metalfisa'!$A13) -> 0 | AR13: =SUMIFS(METALFISA!$E:$E,METALFISA!$A:$A,'Faltantes Fevereiro- Metalfisa'!AR$3,METALFISA!$B:$B,'Faltantes Fevereiro- Metalfisa'!$A13) -> 0 | AS13: =SUMIFS(METALFISA!$E:$E,METALFISA!$A:$A,'Faltantes Fevereiro- Metalfisa'!AS$3,METALFISA!$B:$B,'Faltantes Fevereiro- Metalfisa'!$A13) -> 0 | AU13: 0 | AV13: 0 | AW13: 0 | AX13: 0 | AY13: 0 | AZ13: 0 | BA13: 0 | BB13: 0 | BC13: 0 | BD13: 0 | BE13: 0 | BF13: 0 | BG13: 0 | BH13: 0 | BI13: 0 | BJ13: 0 | BK13: 0 | BL13: 0 | BM13: 4 | BN13: 0 | BO13: 0 | BP13: 0 | BQ13: 0 | BR13: 0 | BS13: 0 | BT13: 0 | BU13: 0 | BV13: 0 | BW13: 0 | BX13: 0 | BY13: 0 | BZ13: 0 | CA13: 0 | CB13: 0 | CC13: 0 | CD13: 0 | CE13: 0 | CF13: 0 | CG13: 0 | CH13: 0 | CI13: 0 | CJ13: 0 | CK13: 0 | CL13: 0
A14: 13.03.00110 | B14: DMC-214 - FIXACAO DO VIDRO NA PORTA \ AA_0214_02 | C14: 0 | D14: 0 | E14: 0 | F14: 0 | G14: 4 | H14: =IFERROR(VLOOKUP(A14,[1]FALTANTES!$A:$AB,28,FALSE),"-") -> 0 | I14: =IFERROR(VLOOKUP(A14,[1]FALTANTES!$A:$AC,29,FALSE),"-") -> 0 | J14: =IFERROR(VLOOKUP(A14,[1]FALTANTES!$A:$AD,30,FALSE),"-") -> -4 | K14: 0 | L14: =SUM(M14:AS14) -> 4 | M14: =SUMIFS(METALFISA!$E:$E,METALFISA!$A:$A,'Faltantes Fevereiro- Metalfisa'!M$3,METALFISA!$B:$B,'Faltantes Fevereiro- Metalfisa'!$A14) -> 0 | N14: =SUMIFS(METALFISA!$E:$E,METALFISA!$A:$A,'Faltantes Fevereiro- Metalfisa'!N$3,METALFISA!$B:$B,'Faltantes Fevereiro- Metalfisa'!$A14) -> 0 | O14: =SUMIFS(METALFISA!$E:$E,METALFISA!$A:$A,'Faltantes Fevereiro- Metalfisa'!O$3,METALFISA!$B:$B,'Faltantes Fevereiro- Metalfisa'!$A14) -> 0 | P14: =SUMIFS(METALFISA!$E:$E,METALFISA!$A:$A,'Faltantes Fevereiro- Metalfisa'!P$3,METALFISA!$B:$B,'Faltantes Fevereiro- Metalfisa'!$A14) -> 0 | Q14: =SUMIFS(METALFISA!$E:$E,METALFISA!$A:$A,'Faltantes Fevereiro- Metalfisa'!Q$3,METALFISA!$B:$B,'Faltantes Fevereiro- Metalfisa'!$A14) -> 0 | R14: =SUMIFS(METALFISA!$E:$E,METALFISA!$A:$A,'Faltantes Fevereiro- Metalfisa'!R$3,METALFISA!$B:$B,'Faltantes Fevereiro- Metalfisa'!$A14) -> 0 | S14: =SUMIFS(METALFISA!$E:$E,METALFISA!$A:$A,'Faltantes Fevereiro- Metalfisa'!S$3,METALFISA!$B:$B,'Faltantes Fevereiro- Metalfisa'!$A14) -> 0 | T14: =SUMIFS(METALFISA!$E:$E,METALFISA!$A:$A,'Faltantes Fevereiro- Metalfisa'!T$3,METALFISA!$B:$B,'Faltantes Fevereiro- Metalfisa'!$A14) -> 0 | ... AP14: =SUMIFS(METALFISA!$E:$E,METALFISA!$A:$A,'Faltantes Fevereiro- Metalfisa'!AP$3,METALFISA!$B:$B,'Faltantes Fevereiro- Metalfisa'!$A14) -> 0 | AR14: =SUMIFS(METALFISA!$E:$E,METALFISA!$A:$A,'Faltantes Fevereiro- Metalfisa'!AR$3,METALFISA!$B:$B,'Faltantes Fevereiro- Metalfisa'!$A14) -> 0 | AS14: =SUMIFS(METALFISA!$E:$E,METALFISA!$A:$A,'Faltantes Fevereiro- Metalfisa'!AS$3,METALFISA!$B:$B,'Faltantes Fevereiro- Metalfisa'!$A14) -> 0 | AU14: 0 | AV14: 0 | AW14: 0 | AX14: 0 | AY14: 0 | AZ14: 0 | BA14: 0 | BB14: 0 | BC14: 0 | BD14: 0 | BE14: 0 | BF14: 0 | BG14: 0 | BH14: 0 | BI14: 0 | BJ14: 0 | BK14: 0 | BL14: 0 | BM14: 2 | BN14: 0 | BO14: 0 | BP14: 0 | BQ14: 0 | BR14: 0 | BS14: 0 | BT14: 0 | BU14: 0 | BV14: 0 | BW14: 0 | BX14: 0 | BY14: 0 | BZ14: 0 | CA14: 0 | CB14: 0 | CC14: 0 | CD14: 0 | CE14: 0 | CF14: 0 | CG14: 0 | CH14: 0 | CI14: 0 | CJ14: 0 | CK14: 0 | CL14: 0
A15: 13.03.00111 | B15: DMC-216 - ACABAMENTO FRONTAL \ AA_0216_04 | C15: 0 | D15: 0 | E15: 0 | F15: 0 | G15: 6 | H15: =IFERROR(VLOOKUP(A15,[1]FALTANTES!$A:$AB,28,FALSE),"-") -> 0 | I15: =IFERROR(VLOOKUP(A15,[1]FALTANTES!$A:$AC,29,FALSE),"-") -> 0 | J15: =IFERROR(VLOOKUP(A15,[1]FALTANTES!$A:$AD,30,FALSE),"-") -> -6 | K15: 0 | L15: =SUM(M15:AS15) -> 6 | M15: =SUMIFS(METALFISA!$E:$E,METALFISA!$A:$A,'Faltantes Fevereiro- Metalfisa'!M$3,METALFISA!$B:$B,'Faltantes Fevereiro- Metalfisa'!$A15) -> 0 | N15: =SUMIFS(METALFISA!$E:$E,METALFISA!$A:$A,'Faltantes Fevereiro- Metalfisa'!N$3,METALFISA!$B:$B,'Faltantes Fevereiro- Metalfisa'!$A15) -> 0 | O15: =SUMIFS(METALFISA!$E:$E,METALFISA!$A:$A,'Faltantes Fevereiro- Metalfisa'!O$3,METALFISA!$B:$B,'Faltantes Fevereiro- Metalfisa'!$A15) -> 0 | P15: =SUMIFS(METALFISA!$E:$E,METALFISA!$A:$A,'Faltantes Fevereiro- Metalfisa'!P$3,METALFISA!$B:$B,'Faltantes Fevereiro- Metalfisa'!$A15) -> 0 | Q15: =SUMIFS(METALFISA!$E:$E,METALFISA!$A:$A,'Faltantes Fevereiro- Metalfisa'!Q$3,METALFISA!$B:$B,'Faltantes Fevereiro- Metalfisa'!$A15) -> 0 | R15: =SUMIFS(METALFISA!$E:$E,METALFISA!$A:$A,'Faltantes Fevereiro- Metalfisa'!R$3,METALFISA!$B:$B,'Faltantes Fevereiro- Metalfisa'!$A15) -> 0 | S15: =SUMIFS(METALFISA!$E:$E,METALFISA!$A:$A,'Faltantes Fevereiro- Metalfisa'!S$3,METALFISA!$B:$B,'Faltantes Fevereiro- Metalfisa'!$A15) -> 0 | T15: =SUMIFS(METALFISA!$E:$E,METALFISA!$A:$A,'Faltantes Fevereiro- Metalfisa'!T$3,METALFISA!$B:$B,'Faltantes Fevereiro- Metalfisa'!$A15) -> 0 | ... AP15: =SUMIFS(METALFISA!$E:$E,METALFISA!$A:$A,'Faltantes Fevereiro- Metalfisa'!AP$3,METALFISA!$B:$B,'Faltantes Fevereiro- Metalfisa'!$A15) -> 0 | AR15: =SUMIFS(METALFISA!$E:$E,METALFISA!$A:$A,'Faltantes Fevereiro- Metalfisa'!AR$3,METALFISA!$B:$B,'Faltantes Fevereiro- Metalfisa'!$A15) -> 0 | AS15: =SUMIFS(METALFISA!$E:$E,METALFISA!$A:$A,'Faltantes Fevereiro- Metalfisa'!AS$3,METALFISA!$B:$B,'Faltantes Fevereiro- Metalfisa'!$A15) -> 0 | AU15: 0 | AV15: 0 | AW15: 0 | AX15: 0 | AY15: 0 | AZ15: 0 | BA15: 0 | BB15: 0 | BC15: 0 | BD15: 0 | BE15: 0 | BF15: 0 | BG15: 0 | BH15: 0 | BI15: 0 | BJ15: 0 | BK15: 0 | BL15: 0 | BM15: 2 | BN15: 0 | BO15: 0 | BP15: 0 | BQ15: 0 | BR15: 0 | BS15: 0 | BT15: 0 | BU15: 0 | BV15: 0 | BW15: 0 | BX15: 0 | BY15: 0 | BZ15: 0 | CA15: 0 | CB15: 0 | CC15: 0 | CD15: 0 | CE15: 0 | CF15: 0 | CG15: 0 | CH15: 0 | CI15: 0 | CJ15: 0 | CK15: 0 | CL15: 0
A16: 13.03.00112 | B16: SUPORTE LED \ AA_0223_09 | C16: 0 | D16: 0 | E16: 0 | F16: 0 | G16: 6 | H16: =IFERROR(VLOOKUP(A16,[1]FALTANTES!$A:$AB,28,FALSE),"-") -> 0 | I16: =IFERROR(VLOOKUP(A16,[1]FALTANTES!$A:$AC,29,FALSE),"-") -> 0 | J16: =IFERROR(VLOOKUP(A16,[1]FALTANTES!$A:$AD,30,FALSE),"-") -> -6 | K16: 0 | L16: =SUM(M16:AS16) -> 6 | M16: =SUMIFS(METALFISA!$E:$E,METALFISA!$A:$A,'Faltantes Fevereiro- Metalfisa'!M$3,METALFISA!$B:$B,'Faltantes Fevereiro- Metalfisa'!$A16) -> 0 | N16: =SUMIFS(METALFISA!$E:$E,METALFISA!$A:$A,'Faltantes Fevereiro- Metalfisa'!N$3,METALFISA!$B:$B,'Faltantes Fevereiro- Metalfisa'!$A16) -> 0 | O16: =SUMIFS(METALFISA!$E:$E,METALFISA!$A:$A,'Faltantes Fevereiro- Metalfisa'!O$3,METALFISA!$B:$B,'Faltantes Fevereiro- Metalfisa'!$A16) -> 0 | P16: =SUMIFS(METALFISA!$E:$E,METALFISA!$A:$A,'Faltantes Fevereiro- Metalfisa'!P$3,METALFISA!$B:$B,'Faltantes Fevereiro- Metalfisa'!$A16) -> 0 | Q16: =SUMIFS(METALFISA!$E:$E,METALFISA!$A:$A,'Faltantes Fevereiro- Metalfisa'!Q$3,METALFISA!$B:$B,'Faltantes Fevereiro- Metalfisa'!$A16) -> 0 | R16: =SUMIFS(METALFISA!$E:$E,METALFISA!$A:$A,'Faltantes Fevereiro- Metalfisa'!R$3,METALFISA!$B:$B,'Faltantes Fevereiro- Metalfisa'!$A16) -> 0 | S16: =SUMIFS(METALFISA!$E:$E,METALFISA!$A:$A,'Faltantes Fevereiro- Metalfisa'!S$3,METALFISA!$B:$B,'Faltantes Fevereiro- Metalfisa'!$A16) -> 0 | T16: =SUMIFS(METALFISA!$E:$E,METALFISA!$A:$A,'Faltantes Fevereiro- Metalfisa'!T$3,METALFISA!$B:$B,'Faltantes Fevereiro- Metalfisa'!$A16) -> 0 | ... AP16: =SUMIFS(METALFISA!$E:$E,METALFISA!$A:$A,'Faltantes Fevereiro- Metalfisa'!AP$3,METALFISA!$B:$B,'Faltantes Fevereiro- Metalfisa'!$A16) -> 0 | AR16: =SUMIFS(METALFISA!$E:$E,METALFISA!$A:$A,'Faltantes Fevereiro- Metalfisa'!AR$3,METALFISA!$B:$B,'Faltantes Fevereiro- Metalfisa'!$A16) -> 0 | AS16: =SUMIFS(METALFISA!$E:$E,METALFISA!$A:$A,'Faltantes Fevereiro- Metalfisa'!AS$3,METALFISA!$B:$B,'Faltantes Fevereiro- Metalfisa'!$A16) -> 0 | AU16: 0 | AV16: 0 | AW16: 0 | AX16: 0 | AY16: 0 | AZ16: 0 | BA16: 0 | BB16: 0 | BC16: 0 | BD16: 0 | BE16: 0 | BF16: 0 | BG16: 0 | BH16: 0 | BI16: 0 | BJ16: 0 | BK16: 0 | BL16: 0 | BM16: 2 | BN16: 0 | BO16: 0 | BP16: 0 | BQ16: 0 | BR16: 0 | BS16: 0 | BT16: 0 | BU16: 0 | BV16: 0 | BW16: 0 | BX16: 0 | BY16: 0 | BZ16: 0 | CA16: 0 | CB16: 0 | CC16: 0 | CD16: 0 | CE16: 0 | CF16: 0 | CG16: 0 | CH16: 0 | CI16: 0 | CJ16: 0 | CK16: 0 | CL16: 0
A17: 13.03.00123 | B17: DMC-274 - BANDEJA DA MESA \ AA_0274_08 | C17: 0 | D17: 0 | E17: 0 | F17: 0 | G17: 3 | H17: =IFERROR(VLOOKUP(A17,[1]FALTANTES!$A:$AB,28,FALSE),"-") -> 0 | I17: =IFERROR(VLOOKUP(A17,[1]FALTANTES!$A:$AC,29,FALSE),"-") -> 0 | J17: =IFERROR(VLOOKUP(A17,[1]FALTANTES!$A:$AD,30,FALSE),"-") -> -3 | K17: 0 | L17: =SUM(M17:AS17) -> 3 | M17: =SUMIFS(METALFISA!$E:$E,METALFISA!$A:$A,'Faltantes Fevereiro- Metalfisa'!M$3,METALFISA!$B:$B,'Faltantes Fevereiro- Metalfisa'!$A17) -> 0 | N17: =SUMIFS(METALFISA!$E:$E,METALFISA!$A:$A,'Faltantes Fevereiro- Metalfisa'!N$3,METALFISA!$B:$B,'Faltantes Fevereiro- Metalfisa'!$A17) -> 0 | O17: =SUMIFS(METALFISA!$E:$E,METALFISA!$A:$A,'Faltantes Fevereiro- Metalfisa'!O$3,METALFISA!$B:$B,'Faltantes Fevereiro- Metalfisa'!$A17) -> 0 | P17: =SUMIFS(METALFISA!$E:$E,METALFISA!$A:$A,'Faltantes Fevereiro- Metalfisa'!P$3,METALFISA!$B:$B,'Faltantes Fevereiro- Metalfisa'!$A17) -> 0 | Q17: =SUMIFS(METALFISA!$E:$E,METALFISA!$A:$A,'Faltantes Fevereiro- Metalfisa'!Q$3,METALFISA!$B:$B,'Faltantes Fevereiro- Metalfisa'!$A17) -> 0 | R17: =SUMIFS(METALFISA!$E:$E,METALFISA!$A:$A,'Faltantes Fevereiro- Metalfisa'!R$3,METALFISA!$B:$B,'Faltantes Fevereiro- Metalfisa'!$A17) -> 0 | S17: =SUMIFS(METALFISA!$E:$E,METALFISA!$A:$A,'Faltantes Fevereiro- Metalfisa'!S$3,METALFISA!$B:$B,'Faltantes Fevereiro- Metalfisa'!$A17) -> 0 | T17: =SUMIFS(METALFISA!$E:$E,METALFISA!$A:$A,'Faltantes Fevereiro- Metalfisa'!T$3,METALFISA!$B:$B,'Faltantes Fevereiro- Metalfisa'!$A17) -> 0 | ... AP17: =SUMIFS(METALFISA!$E:$E,METALFISA!$A:$A,'Faltantes Fevereiro- Metalfisa'!AP$3,METALFISA!$B:$B,'Faltantes Fevereiro- Metalfisa'!$A17) -> 0 | AR17: =SUMIFS(METALFISA!$E:$E,METALFISA!$A:$A,'Faltantes Fevereiro- Metalfisa'!AR$3,METALFISA!$B:$B,'Faltantes Fevereiro- Metalfisa'!$A17) -> 0 | AS17: =SUMIFS(METALFISA!$E:$E,METALFISA!$A:$A,'Faltantes Fevereiro- Metalfisa'!AS$3,METALFISA!$B:$B,'Faltantes Fevereiro- Metalfisa'!$A17) -> 0 | AU17: 0 | AV17: 0 | AW17: 0 | AX17: 0 | AY17: 0 | AZ17: 0 | BA17: 0 | BB17: 0 | BC17: 0 | BD17: 0 | BE17: 0 | BF17: 0 | BG17: 0 | BH17: 0 | BI17: 0 | BJ17: 0 | BK17: 0 | BL17: 0 | BM17: 1 | BN17: 0 | BO17: 0 | BP17: 0 | BQ17: 0 | BR17: 0 | BS17: 0 | BT17: 0 | BU17: 0 | BV17: 0 | BW17: 0 | BX17: 0 | BY17: 0 | BZ17: 0 | CA17: 0 | CB17: 0 | CC17: 0 | CD17: 0 | CE17: 0 | CF17: 0 | CG17: 0 | CH17: 0 | CI17: 0 | CJ17: 0 | CK17: 0 | CL17: 0
A18: 13.03.00124 | B18: DMC-281 - TAMPA PORTA MENOR ESQUERDA \ AA_0281_04 | C18: 0 | D18: 0 | E18: 0 | F18: 0 | G18: 1 | H18: =IFERROR(VLOOKUP(A18,[1]FALTANTES!$A:$AB,28,FALSE),"-") -> 0 | I18: =IFERROR(VLOOKUP(A18,[1]FALTANTES!$A:$AC,29,FALSE),"-") -> 0 | J18: =IFERROR(VLOOKUP(A18,[1]FALTANTES!$A:$AD,30,FALSE),"-") -> -1 | K18: 0 | L18: =SUM(M18:AS18) -> 1 | M18: =SUMIFS(METALFISA!$E:$E,METALFISA!$A:$A,'Faltantes Fevereiro- Metalfisa'!M$3,METALFISA!$B:$B,'Faltantes Fevereiro- Metalfisa'!$A18) -> 0 | N18: =SUMIFS(METALFISA!$E:$E,METALFISA!$A:$A,'Faltantes Fevereiro- Metalfisa'!N$3,METALFISA!$B:$B,'Faltantes Fevereiro- Metalfisa'!$A18) -> 0 | O18: =SUMIFS(METALFISA!$E:$E,METALFISA!$A:$A,'Faltantes Fevereiro- Metalfisa'!O$3,METALFISA!$B:$B,'Faltantes Fevereiro- Metalfisa'!$A18) -> 0 | P18: =SUMIFS(METALFISA!$E:$E,METALFISA!$A:$A,'Faltantes Fevereiro- Metalfisa'!P$3,METALFISA!$B:$B,'Faltantes Fevereiro- Metalfisa'!$A18) -> 0 | Q18: =SUMIFS(METALFISA!$E:$E,METALFISA!$A:$A,'Faltantes Fevereiro- Metalfisa'!Q$3,METALFISA!$B:$B,'Faltantes Fevereiro- Metalfisa'!$A18) -> 0 | R18: =SUMIFS(METALFISA!$E:$E,METALFISA!$A:$A,'Faltantes Fevereiro- Metalfisa'!R$3,METALFISA!$B:$B,'Faltantes Fevereiro- Metalfisa'!$A18) -> 0 | S18: =SUMIFS(METALFISA!$E:$E,METALFISA!$A:$A,'Faltantes Fevereiro- Metalfisa'!S$3,METALFISA!$B:$B,'Faltantes Fevereiro- Metalfisa'!$A18) -> 0 | T18: =SUMIFS(METALFISA!$E:$E,METALFISA!$A:$A,'Faltantes Fevereiro- Metalfisa'!T$3,METALFISA!$B:$B,'Faltantes Fevereiro- Metalfisa'!$A18) -> 0 | ... AP18: =SUMIFS(METALFISA!$E:$E,METALFISA!$A:$A,'Faltantes Fevereiro- Metalfisa'!AP$3,METALFISA!$B:$B,'Faltantes Fevereiro- Metalfisa'!$A18) -> 0 | AR18: =SUMIFS(METALFISA!$E:$E,METALFISA!$A:$A,'Faltantes Fevereiro- Metalfisa'!AR$3,METALFISA!$B:$B,'Faltantes Fevereiro- Metalfisa'!$A18) -> 0 | AS18: =SUMIFS(METALFISA!$E:$E,METALFISA!$A:$A,'Faltantes Fevereiro- Metalfisa'!AS$3,METALFISA!$B:$B,'Faltantes Fevereiro- Metalfisa'!$A18) -> 0 | AU18: 0 | AV18: 0 | AW18: 0 | AX18: 0 | AY18: 0 | AZ18: 0 | BA18: 0 | BB18: 0 | BC18: 0 | BD18: 0 | BE18: 0 | BF18: 0 | BG18: 0 | BH18: 0 | BI18: 0 | BJ18: 0 | BK18: 0 | BL18: 0 | BM18: 1 | BN18: 0 | BO18: 0 | BP18: 0 | BQ18: 0 | BR18: 0 | BS18: 0 | BT18: 0 | BU18: 0 | BV18: 0 | BW18: 0 | BX18: 0 | BY18: 0 | BZ18: 0 | CA18: 0 | CB18: 0 | CC18: 0 | CD18: 0 | CE18: 0 | CF18: 0 | CG18: 0 | CH18: 0 | CI18: 0 | CJ18: 0 | CK18: 0 | CL18: 0
A19: 13.03.00125 | B19: DMC-282 - TAMPA PORTA MAIOR \ AA_0282_06 | C19: 0 | D19: 0 | E19: 0 | F19: 0 | G19: 3 | H19: =IFERROR(VLOOKUP(A19,[1]FALTANTES!$A:$AB,28,FALSE),"-") -> 0 | I19: =IFERROR(VLOOKUP(A19,[1]FALTANTES!$A:$AC,29,FALSE),"-") -> 0 | J19: =IFERROR(VLOOKUP(A19,[1]FALTANTES!$A:$AD,30,FALSE),"-") -> -3 | K19: 0 | L19: =SUM(M19:AS19) -> 3 | M19: =SUMIFS(METALFISA!$E:$E,METALFISA!$A:$A,'Faltantes Fevereiro- Metalfisa'!M$3,METALFISA!$B:$B,'Faltantes Fevereiro- Metalfisa'!$A19) -> 0 | N19: =SUMIFS(METALFISA!$E:$E,METALFISA!$A:$A,'Faltantes Fevereiro- Metalfisa'!N$3,METALFISA!$B:$B,'Faltantes Fevereiro- Metalfisa'!$A19) -> 0 | O19: =SUMIFS(METALFISA!$E:$E,METALFISA!$A:$A,'Faltantes Fevereiro- Metalfisa'!O$3,METALFISA!$B:$B,'Faltantes Fevereiro- Metalfisa'!$A19) -> 0 | P19: =SUMIFS(METALFISA!$E:$E,METALFISA!$A:$A,'Faltantes Fevereiro- Metalfisa'!P$3,METALFISA!$B:$B,'Faltantes Fevereiro- Metalfisa'!$A19) -> 0 | Q19: =SUMIFS(METALFISA!$E:$E,METALFISA!$A:$A,'Faltantes Fevereiro- Metalfisa'!Q$3,METALFISA!$B:$B,'Faltantes Fevereiro- Metalfisa'!$A19) -> 0 | R19: =SUMIFS(METALFISA!$E:$E,METALFISA!$A:$A,'Faltantes Fevereiro- Metalfisa'!R$3,METALFISA!$B:$B,'Faltantes Fevereiro- Metalfisa'!$A19) -> 0 | S19: =SUMIFS(METALFISA!$E:$E,METALFISA!$A:$A,'Faltantes Fevereiro- Metalfisa'!S$3,METALFISA!$B:$B,'Faltantes Fevereiro- Metalfisa'!$A19) -> 0 | T19: =SUMIFS(METALFISA!$E:$E,METALFISA!$A:$A,'Faltantes Fevereiro- Metalfisa'!T$3,METALFISA!$B:$B,'Faltantes Fevereiro- Metalfisa'!$A19) -> 0 | ... AP19: =SUMIFS(METALFISA!$E:$E,METALFISA!$A:$A,'Faltantes Fevereiro- Metalfisa'!AP$3,METALFISA!$B:$B,'Faltantes Fevereiro- Metalfisa'!$A19) -> 0 | AR19: =SUMIFS(METALFISA!$E:$E,METALFISA!$A:$A,'Faltantes Fevereiro- Metalfisa'!AR$3,METALFISA!$B:$B,'Faltantes Fevereiro- Metalfisa'!$A19) -> 0 | AS19: =SUMIFS(METALFISA!$E:$E,METALFISA!$A:$A,'Faltantes Fevereiro- Metalfisa'!AS$3,METALFISA!$B:$B,'Faltantes Fevereiro- Metalfisa'!$A19) -> 0 | AU19: 0 | AV19: 0 | AW19: 0 | AX19: 0 | AY19: 0 | AZ19: 0 | BA19: 0 | BB19: 0 | BC19: 0 | BD19: 0 | BE19: 0 | BF19: 0 | BG19: 0 | BH19: 0 | BI19: 0 | BJ19: 0 | BK19: 0 | BL19: 0 | BM19: 1 | BN19: 0 | BO19: 0 | BP19: 0 | BQ19: 0 | BR19: 0 | BS19: 0 | BT19: 0 | BU19: 0 | BV19: 0 | BW19: 0 | BX19: 0 | BY19: 0 | BZ19: 0 | CA19: 0 | CB19: 0 | CC19: 0 | CD19: 0 | CE19: 0 | CF19: 0 | CG19: 0 | CH19: 0 | CI19: 0 | CJ19: 0 | CK19: 0 | CL19: 0
A20: 13.03.00143 | B20: BASE SOLDADA \ AA_0387_08 | C20: 0 | D20: 0 | E20: 0 | F20: 0 | G20: 3 | H20: =IFERROR(VLOOKUP(A20,[1]FALTANTES!$A:$AB,28,FALSE),"-") -> 0 | I20: =IFERROR(VLOOKUP(A20,[1]FALTANTES!$A:$AC,29,FALSE),"-") -> 0 | J20: =IFERROR(VLOOKUP(A20,[1]FALTANTES!$A:$AD,30,FALSE),"-") -> -3 | K20: 0 | L20: =SUM(M20:AS20) -> 3 | M20: =SUMIFS(METALFISA!$E:$E,METALFISA!$A:$A,'Faltantes Fevereiro- Metalfisa'!M$3,METALFISA!$B:$B,'Faltantes Fevereiro- Metalfisa'!$A20) -> 0 | N20: =SUMIFS(METALFISA!$E:$E,METALFISA!$A:$A,'Faltantes Fevereiro- Metalfisa'!N$3,METALFISA!$B:$B,'Faltantes Fevereiro- Metalfisa'!$A20) -> 0 | O20: =SUMIFS(METALFISA!$E:$E,METALFISA!$A:$A,'Faltantes Fevereiro- Metalfisa'!O$3,METALFISA!$B:$B,'Faltantes Fevereiro- Metalfisa'!$A20) -> 0 | P20: =SUMIFS(METALFISA!$E:$E,METALFISA!$A:$A,'Faltantes Fevereiro- Metalfisa'!P$3,METALFISA!$B:$B,'Faltantes Fevereiro- Metalfisa'!$A20) -> 0 | Q20: =SUMIFS(METALFISA!$E:$E,METALFISA!$A:$A,'Faltantes Fevereiro- Metalfisa'!Q$3,METALFISA!$B:$B,'Faltantes Fevereiro- Metalfisa'!$A20) -> 0 | R20: =SUMIFS(METALFISA!$E:$E,METALFISA!$A:$A,'Faltantes Fevereiro- Metalfisa'!R$3,METALFISA!$B:$B,'Faltantes Fevereiro- Metalfisa'!$A20) -> 0 | S20: =SUMIFS(METALFISA!$E:$E,METALFISA!$A:$A,'Faltantes Fevereiro- Metalfisa'!S$3,METALFISA!$B:$B,'Faltantes Fevereiro- Metalfisa'!$A20) -> 0 | T20: =SUMIFS(METALFISA!$E:$E,METALFISA!$A:$A,'Faltantes Fevereiro- Metalfisa'!T$3,METALFISA!$B:$B,'Faltantes Fevereiro- Metalfisa'!$A20) -> 0 | ... AP20: =SUMIFS(METALFISA!$E:$E,METALFISA!$A:$A,'Faltantes Fevereiro- Metalfisa'!AP$3,METALFISA!$B:$B,'Faltantes Fevereiro- Metalfisa'!$A20) -> 0 | AR20: =SUMIFS(METALFISA!$E:$E,METALFISA!$A:$A,'Faltantes Fevereiro- Metalfisa'!AR$3,METALFISA!$B:$B,'Faltantes Fevereiro- Metalfisa'!$A20) -> 0 | AS20: =SUMIFS(METALFISA!$E:$E,METALFISA!$A:$A,'Faltantes Fevereiro- Metalfisa'!AS$3,METALFISA!$B:$B,'Faltantes Fevereiro- Metalfisa'!$A20) -> 0 | AU20: 0 | AV20: 0 | AW20: 0 | AX20: 0 | AY20: 0 | AZ20: 0 | BA20: 0 | BB20: 0 | BC20: 0 | BD20: 0 | BE20: 0 | BF20: 0 | BG20: 0 | BH20: 0 | BI20: 0 | BJ20: 0 | BK20: 0 | BL20: 0 | BM20: 1 | BN20: 0 | BO20: 0 | BP20: 0 | BQ20: 0 | BR20: 0 | BS20: 0 | BT20: 0 | BU20: 0 | BV20: 0 | BW20: 0 | BX20: 0 | BY20: 0 | BZ20: 0 | CA20: 0 | CB20: 0 | CC20: 0 | CD20: 0 | CE20: 0 | CF20: 0 | CG20: 0 | CH20: 0 | CI20: 0 | CJ20: 0 | CK20: 0 | CL20: 0
A21: 13.03.00164 | B21: DMC-438 - PORTA MAIOR DIREITA FLATSCAN \ AA_0438_04 | C21: 0 | D21: 0 | E21: 0 | F21: 0 | G21: 3 | H21: =IFERROR(VLOOKUP(A21,[1]FALTANTES!$A:$AB,28,FALSE),"-") -> 0 | I21: =IFERROR(VLOOKUP(A21,[1]FALTANTES!$A:$AC,29,FALSE),"-") -> 0 | J21: =IFERROR(VLOOKUP(A21,[1]FALTANTES!$A:$AD,30,FALSE),"-") -> -3 | K21: 0 | L21: =SUM(M21:AS21) -> 3 | M21: =SUMIFS(METALFISA!$E:$E,METALFISA!$A:$A,'Faltantes Fevereiro- Metalfisa'!M$3,METALFISA!$B:$B,'Faltantes Fevereiro- Metalfisa'!$A21) -> 0 | N21: =SUMIFS(METALFISA!$E:$E,METALFISA!$A:$A,'Faltantes Fevereiro- Metalfisa'!N$3,METALFISA!$B:$B,'Faltantes Fevereiro- Metalfisa'!$A21) -> 0 | O21: =SUMIFS(METALFISA!$E:$E,METALFISA!$A:$A,'Faltantes Fevereiro- Metalfisa'!O$3,METALFISA!$B:$B,'Faltantes Fevereiro- Metalfisa'!$A21) -> 0 | P21: =SUMIFS(METALFISA!$E:$E,METALFISA!$A:$A,'Faltantes Fevereiro- Metalfisa'!P$3,METALFISA!$B:$B,'Faltantes Fevereiro- Metalfisa'!$A21) -> 0 | Q21: =SUMIFS(METALFISA!$E:$E,METALFISA!$A:$A,'Faltantes Fevereiro- Metalfisa'!Q$3,METALFISA!$B:$B,'Faltantes Fevereiro- Metalfisa'!$A21) -> 0 | R21: =SUMIFS(METALFISA!$E:$E,METALFISA!$A:$A,'Faltantes Fevereiro- Metalfisa'!R$3,METALFISA!$B:$B,'Faltantes Fevereiro- Metalfisa'!$A21) -> 0 | S21: =SUMIFS(METALFISA!$E:$E,METALFISA!$A:$A,'Faltantes Fevereiro- Metalfisa'!S$3,METALFISA!$B:$B,'Faltantes Fevereiro- Metalfisa'!$A21) -> 0 | T21: =SUMIFS(METALFISA!$E:$E,METALFISA!$A:$A,'Faltantes Fevereiro- Metalfisa'!T$3,METALFISA!$B:$B,'Faltantes Fevereiro- Metalfisa'!$A21) -> 0 | ... AP21: =SUMIFS(METALFISA!$E:$E,METALFISA!$A:$A,'Faltantes Fevereiro- Metalfisa'!AP$3,METALFISA!$B:$B,'Faltantes Fevereiro- Metalfisa'!$A21) -> 0 | AR21: =SUMIFS(METALFISA!$E:$E,METALFISA!$A:$A,'Faltantes Fevereiro- Metalfisa'!AR$3,METALFISA!$B:$B,'Faltantes Fevereiro- Metalfisa'!$A21) -> 0 | AS21: =SUMIFS(METALFISA!$E:$E,METALFISA!$A:$A,'Faltantes Fevereiro- Metalfisa'!AS$3,METALFISA!$B:$B,'Faltantes Fevereiro- Metalfisa'!$A21) -> 0 | AU21: 0 | AV21: 0 | AW21: 0 | AX21: 0 | AY21: 0 | AZ21: 0 | BA21: 0 | BB21: 0 | BC21: 0 | BD21: 0 | BE21: 0 | BF21: 0 | BG21: 0 | BH21: 0 | BI21: 0 | BJ21: 0 | BK21: 0 | BL21: 0 | BM21: 1 | BN21: 0 | BO21: 0 | BP21: 0 | BQ21: 0 | BR21: 0 | BS21: 0 | BT21: 0 | BU21: 0 | BV21: 0 | BW21: 0 | BX21: 0 | BY21: 0 | BZ21: 0 | CA21: 0 | CB21: 0 | CC21: 0 | CD21: 0 | CE21: 0 | CF21: 0 | CG21: 0 | CH21: 0 | CI21: 0 | CJ21: 0 | CK21: 0 | CL21: 0
A22: 13.03.00165 | B22: DMC-440 - CHASSI PROT. MESA ESQ. FLAT \ AA_0440_09 | C22: 0 | D22: 0 | E22: 0 | F22: 0 | G22: 3 | H22: =IFERROR(VLOOKUP(A22,[1]FALTANTES!$A:$AB,28,FALSE),"-") -> 0 | I22: =IFERROR(VLOOKUP(A22,[1]FALTANTES!$A:$AC,29,FALSE),"-") -> 0 | J22: =IFERROR(VLOOKUP(A22,[1]FALTANTES!$A:$AD,30,FALSE),"-") -> -3 | K22: 0 | L22: =SUM(M22:AS22) -> 3 | M22: =SUMIFS(METALFISA!$E:$E,METALFISA!$A:$A,'Faltantes Fevereiro- Metalfisa'!M$3,METALFISA!$B:$B,'Faltantes Fevereiro- Metalfisa'!$A22) -> 0 | N22: =SUMIFS(METALFISA!$E:$E,METALFISA!$A:$A,'Faltantes Fevereiro- Metalfisa'!N$3,METALFISA!$B:$B,'Faltantes Fevereiro- Metalfisa'!$A22) -> 0 | O22: =SUMIFS(METALFISA!$E:$E,METALFISA!$A:$A,'Faltantes Fevereiro- Metalfisa'!O$3,METALFISA!$B:$B,'Faltantes Fevereiro- Metalfisa'!$A22) -> 0 | P22: =SUMIFS(METALFISA!$E:$E,METALFISA!$A:$A,'Faltantes Fevereiro- Metalfisa'!P$3,METALFISA!$B:$B,'Faltantes Fevereiro- Metalfisa'!$A22) -> 0 | Q22: =SUMIFS(METALFISA!$E:$E,METALFISA!$A:$A,'Faltantes Fevereiro- Metalfisa'!Q$3,METALFISA!$B:$B,'Faltantes Fevereiro- Metalfisa'!$A22) -> 0 | R22: =SUMIFS(METALFISA!$E:$E,METALFISA!$A:$A,'Faltantes Fevereiro- Metalfisa'!R$3,METALFISA!$B:$B,'Faltantes Fevereiro- Metalfisa'!$A22) -> 0 | S22: =SUMIFS(METALFISA!$E:$E,METALFISA!$A:$A,'Faltantes Fevereiro- Metalfisa'!S$3,METALFISA!$B:$B,'Faltantes Fevereiro- Metalfisa'!$A22) -> 0 | T22: =SUMIFS(METALFISA!$E:$E,METALFISA!$A:$A,'Faltantes Fevereiro- Metalfisa'!T$3,METALFISA!$B:$B,'Faltantes Fevereiro- Metalfisa'!$A22) -> 0 | ... AP22: =SUMIFS(METALFISA!$E:$E,METALFISA!$A:$A,'Faltantes Fevereiro- Metalfisa'!AP$3,METALFISA!$B:$B,'Faltantes Fevereiro- Metalfisa'!$A22) -> 0 | AR22: =SUMIFS(METALFISA!$E:$E,METALFISA!$A:$A,'Faltantes Fevereiro- Metalfisa'!AR$3,METALFISA!$B:$B,'Faltantes Fevereiro- Metalfisa'!$A22) -> 0 | AS22: =SUMIFS(METALFISA!$E:$E,METALFISA!$A:$A,'Faltantes Fevereiro- Metalfisa'!AS$3,METALFISA!$B:$B,'Faltantes Fevereiro- Metalfisa'!$A22) -> 0 | AU22: 0 | AV22: 0 | AW22: 0 | AX22: 0 | AY22: 0 | AZ22: 0 | BA22: 0 | BB22: 0 | BC22: 0 | BD22: 0 | BE22: 0 | BF22: 0 | BG22: 0 | BH22: 0 | BI22: 0 | BJ22: 0 | BK22: 0 | BL22: 0 | BM22: 1 | BN22: 0 | BO22: 0 | BP22: 0 | BQ22: 0 | BR22: 0 | BS22: 0 | BT22: 0 | BU22: 0 | BV22: 0 | BW22: 0 | BX22: 0 | BY22: 0 | BZ22: 0 | CA22: 0 | CB22: 0 | CC22: 0 | CD22: 0 | CE22: 0 | CF22: 0 | CG22: 0 | CH22: 0 | CI22: 0 | CJ22: 0 | CK22: 0 | CL22: 0
A23: 13.03.00166 | B23: DMC-441 - BANDEJA MESA ESQ. FLATSCAN \ AA_0441_07 | C23: 0 | D23: 0 | E23: 0 | F23: 0 | G23: 3 | H23: =IFERROR(VLOOKUP(A23,[1]FALTANTES!$A:$AB,28,FALSE),"-") -> 0 | I23: =IFERROR(VLOOKUP(A23,[1]FALTANTES!$A:$AC,29,FALSE),"-") -> 0 | J23: =IFERROR(VLOOKUP(A23,[1]FALTANTES!$A:$AD,30,FALSE),"-") -> -3 | K23: 0 | L23: =SUM(M23:AS23) -> 3 | M23: =SUMIFS(METALFISA!$E:$E,METALFISA!$A:$A,'Faltantes Fevereiro- Metalfisa'!M$3,METALFISA!$B:$B,'Faltantes Fevereiro- Metalfisa'!$A23) -> 0 | N23: =SUMIFS(METALFISA!$E:$E,METALFISA!$A:$A,'Faltantes Fevereiro- Metalfisa'!N$3,METALFISA!$B:$B,'Faltantes Fevereiro- Metalfisa'!$A23) -> 0 | O23: =SUMIFS(METALFISA!$E:$E,METALFISA!$A:$A,'Faltantes Fevereiro- Metalfisa'!O$3,METALFISA!$B:$B,'Faltantes Fevereiro- Metalfisa'!$A23) -> 0 | P23: =SUMIFS(METALFISA!$E:$E,METALFISA!$A:$A,'Faltantes Fevereiro- Metalfisa'!P$3,METALFISA!$B:$B,'Faltantes Fevereiro- Metalfisa'!$A23) -> 0 | Q23: =SUMIFS(METALFISA!$E:$E,METALFISA!$A:$A,'Faltantes Fevereiro- Metalfisa'!Q$3,METALFISA!$B:$B,'Faltantes Fevereiro- Metalfisa'!$A23) -> 0 | R23: =SUMIFS(METALFISA!$E:$E,METALFISA!$A:$A,'Faltantes Fevereiro- Metalfisa'!R$3,METALFISA!$B:$B,'Faltantes Fevereiro- Metalfisa'!$A23) -> 0 | S23: =SUMIFS(METALFISA!$E:$E,METALFISA!$A:$A,'Faltantes Fevereiro- Metalfisa'!S$3,METALFISA!$B:$B,'Faltantes Fevereiro- Metalfisa'!$A23) -> 0 | T23: =SUMIFS(METALFISA!$E:$E,METALFISA!$A:$A,'Faltantes Fevereiro- Metalfisa'!T$3,METALFISA!$B:$B,'Faltantes Fevereiro- Metalfisa'!$A23) -> 0 | ... AP23: =SUMIFS(METALFISA!$E:$E,METALFISA!$A:$A,'Faltantes Fevereiro- Metalfisa'!AP$3,METALFISA!$B:$B,'Faltantes Fevereiro- Metalfisa'!$A23) -> 0 | AR23: =SUMIFS(METALFISA!$E:$E,METALFISA!$A:$A,'Faltantes Fevereiro- Metalfisa'!AR$3,METALFISA!$B:$B,'Faltantes Fevereiro- Metalfisa'!$A23) -> 0 | AS23: =SUMIFS(METALFISA!$E:$E,METALFISA!$A:$A,'Faltantes Fevereiro- Metalfisa'!AS$3,METALFISA!$B:$B,'Faltantes Fevereiro- Metalfisa'!$A23) -> 0 | AU23: 0 | AV23: 0 | AW23: 0 | AX23: 0 | AY23: 0 | AZ23: 0 | BA23: 0 | BB23: 0 | BC23: 0 | BD23: 0 | BE23: 0 | BF23: 0 | BG23: 0 | BH23: 0 | BI23: 0 | BJ23: 0 | BK23: 0 | BL23: 0 | BM23: 1 | BN23: 0 | BO23: 0 | BP23: 0 | BQ23: 0 | BR23: 0 | BS23: 0 | BT23: 0 | BU23: 0 | BV23: 0 | BW23: 0 | BX23: 0 | BY23: 0 | BZ23: 0 | CA23: 0 | CB23: 0 | CC23: 0 | CD23: 0 | CE23: 0 | CF23: 0 | CG23: 0 | CH23: 0 | CI23: 0 | CJ23: 0 | CK23: 0 | CL23: 0
A24: 13.03.00167 | B24: APOIO MESA ROLETES FLATSCAN / AA_0444_02 | C24: 0 | D24: 0 | E24: 0 | F24: 0 | G24: 8 | H24: =IFERROR(VLOOKUP(A24,[1]FALTANTES!$A:$AB,28,FALSE),"-") -> 0 | I24: =IFERROR(VLOOKUP(A24,[1]FALTANTES!$A:$AC,29,FALSE),"-") -> 0 | J24: =IFERROR(VLOOKUP(A24,[1]FALTANTES!$A:$AD,30,FALSE),"-") -> -8 | K24: 0 | L24: =SUM(M24:AS24) -> 8 | M24: =SUMIFS(METALFISA!$E:$E,METALFISA!$A:$A,'Faltantes Fevereiro- Metalfisa'!M$3,METALFISA!$B:$B,'Faltantes Fevereiro- Metalfisa'!$A24) -> 0 | N24: =SUMIFS(METALFISA!$E:$E,METALFISA!$A:$A,'Faltantes Fevereiro- Metalfisa'!N$3,METALFISA!$B:$B,'Faltantes Fevereiro- Metalfisa'!$A24) -> 0 | O24: =SUMIFS(METALFISA!$E:$E,METALFISA!$A:$A,'Faltantes Fevereiro- Metalfisa'!O$3,METALFISA!$B:$B,'Faltantes Fevereiro- Metalfisa'!$A24) -> 0 | P24: =SUMIFS(METALFISA!$E:$E,METALFISA!$A:$A,'Faltantes Fevereiro- Metalfisa'!P$3,METALFISA!$B:$B,'Faltantes Fevereiro- Metalfisa'!$A24) -> 0 | Q24: =SUMIFS(METALFISA!$E:$E,METALFISA!$A:$A,'Faltantes Fevereiro- Metalfisa'!Q$3,METALFISA!$B:$B,'Faltantes Fevereiro- Metalfisa'!$A24) -> 0 | R24: =SUMIFS(METALFISA!$E:$E,METALFISA!$A:$A,'Faltantes Fevereiro- Metalfisa'!R$3,METALFISA!$B:$B,'Faltantes Fevereiro- Metalfisa'!$A24) -> 0 | S24: =SUMIFS(METALFISA!$E:$E,METALFISA!$A:$A,'Faltantes Fevereiro- Metalfisa'!S$3,METALFISA!$B:$B,'Faltantes Fevereiro- Metalfisa'!$A24) -> 0 | T24: =SUMIFS(METALFISA!$E:$E,METALFISA!$A:$A,'Faltantes Fevereiro- Metalfisa'!T$3,METALFISA!$B:$B,'Faltantes Fevereiro- Metalfisa'!$A24) -> 0 | ... AP24: =SUMIFS(METALFISA!$E:$E,METALFISA!$A:$A,'Faltantes Fevereiro- Metalfisa'!AP$3,METALFISA!$B:$B,'Faltantes Fevereiro- Metalfisa'!$A24) -> 0 | AR24: =SUMIFS(METALFISA!$E:$E,METALFISA!$A:$A,'Faltantes Fevereiro- Metalfisa'!AR$3,METALFISA!$B:$B,'Faltantes Fevereiro- Metalfisa'!$A24) -> 0 | AS24: =SUMIFS(METALFISA!$E:$E,METALFISA!$A:$A,'Faltantes Fevereiro- Metalfisa'!AS$3,METALFISA!$B:$B,'Faltantes Fevereiro- Metalfisa'!$A24) -> 0 | AU24: 0 | AV24: 0 | AW24: 0 | AX24: 0 | AY24: 0 | AZ24: 0 | BA24: 0 | BB24: 0 | BC24: 0 | BD24: 0 | BE24: 0 | BF24: 0 | BG24: 0 | BH24: 0 | BI24: 0 | BJ24: 0 | BK24: 0 | BL24: 0 | BM24: 4 | BN24: 0 | BO24: 0 | BP24: 0 | BQ24: 0 | BR24: 0 | BS24: 0 | BT24: 0 | BU24: 0 | BV24: 0 | BW24: 0 | BX24: 0 | BY24: 0 | BZ24: 0 | CA24: 0 | CB24: 0 | CC24: 0 | CD24: 0 | CE24: 0 | CF24: 0 | CG24: 0 | CH24: 0 | CI24: 0 | CJ24: 0 | CK24: 0 | CL24: 0
... A110: 21.23.02248 | B110: SUPORTE VIDRO BODYSCAN \ AA_7251_00 | C110: 0 | D110: 0 | E110: 0 | F110: 0 | G110: 7 | H110: =IFERROR(VLOOKUP(A110,[1]FALTANTES!$A:$AB,28,FALSE),"-") -> 0 | I110: =IFERROR(VLOOKUP(A110,[1]FALTANTES!$A:$AC,29,FALSE),"-") -> 0 | J110: =IFERROR(VLOOKUP(A110,[1]FALTANTES!$A:$AD,30,FALSE),"-") -> -7 | K110: 0 | L110: =SUM(M110:AS110) -> 3 | M110: =SUMIFS(METALFISA!$E:$E,METALFISA!$A:$A,'Faltantes Fevereiro- Metalfisa'!M$3,METALFISA!$B:$B,'Faltantes Fevereiro- Metalfisa'!$A110) -> 0 | N110: =SUMIFS(METALFISA!$E:$E,METALFISA!$A:$A,'Faltantes Fevereiro- Metalfisa'!N$3,METALFISA!$B:$B,'Faltantes Fevereiro- Metalfisa'!$A110) -> 0 | O110: =SUMIFS(METALFISA!$E:$E,METALFISA!$A:$A,'Faltantes Fevereiro- Metalfisa'!O$3,METALFISA!$B:$B,'Faltantes Fevereiro- Metalfisa'!$A110) -> 0 | P110: =SUMIFS(METALFISA!$E:$E,METALFISA!$A:$A,'Faltantes Fevereiro- Metalfisa'!P$3,METALFISA!$B:$B,'Faltantes Fevereiro- Metalfisa'!$A110) -> 0 | Q110: =SUMIFS(METALFISA!$E:$E,METALFISA!$A:$A,'Faltantes Fevereiro- Metalfisa'!Q$3,METALFISA!$B:$B,'Faltantes Fevereiro- Metalfisa'!$A110) -> 0 | R110: =SUMIFS(METALFISA!$E:$E,METALFISA!$A:$A,'Faltantes Fevereiro- Metalfisa'!R$3,METALFISA!$B:$B,'Faltantes Fevereiro- Metalfisa'!$A110) -> 0 | S110: =SUMIFS(METALFISA!$E:$E,METALFISA!$A:$A,'Faltantes Fevereiro- Metalfisa'!S$3,METALFISA!$B:$B,'Faltantes Fevereiro- Metalfisa'!$A110) -> 0 | T110: =SUMIFS(METALFISA!$E:$E,METALFISA!$A:$A,'Faltantes Fevereiro- Metalfisa'!T$3,METALFISA!$B:$B,'Faltantes Fevereiro- Metalfisa'!$A110) -> 0 | ... AP110: =SUMIFS(METALFISA!$E:$E,METALFISA!$A:$A,'Faltantes Fevereiro- Metalfisa'!AP$3,METALFISA!$B:$B,'Faltantes Fevereiro- Metalfisa'!$A110) -> 0 | AR110: =SUMIFS(METALFISA!$E:$E,METALFISA!$A:$A,'Faltantes Fevereiro- Metalfisa'!AR$3,METALFISA!$B:$B,'Faltantes Fevereiro- Metalfisa'!$A110) -> 0 | AS110: =SUMIFS(METALFISA!$E:$E,METALFISA!$A:$A,'Faltantes Fevereiro- Metalfisa'!AS$3,METALFISA!$B:$B,'Faltantes Fevereiro- Metalfisa'!$A110) -> 0 | AU110: 0 | AV110: 0 | AW110: 0 | AX110: 0 | AY110: 4 | AZ110: 4 | BA110: 0 | BB110: 0 | BC110: 0 | BD110: 0 | BE110: 0 | BF110: 0 | BG110: 0 | BH110: 0 | BI110: 0 | BJ110: 0 | BK110: 0 | BL110: 0 | BM110: 0 | BN110: 0 | BO110: 0 | BP110: 0 | BQ110: 0 | BR110: 0 | BS110: 0 | BT110: 0 | BU110: 0 | BV110: 0 | BW110: 0 | BX110: 0 | BY110: 0 | BZ110: 0 | CA110: 0 | CB110: 0 | CC110: 0 | CD110: 0 | CE110: 0 | CF110: 0 | CG110: 0 | CH110: 0 | CI110: 0 | CJ110: 0 | CK110: 0 | CL110: 0
A111: 21.23.02254 | B111: ACABAMENTO DO FUNDO BODYSCAN \ AA_7257_01 | C111: 6 | D111: 0 | E111: 0 | F111: 0 | G111: 29 | H111: =IFERROR(VLOOKUP(A111,[1]FALTANTES!$A:$AB,28,FALSE),"-") -> 0 | I111: =IFERROR(VLOOKUP(A111,[1]FALTANTES!$A:$AC,29,FALSE),"-") -> 34 | J111: =IFERROR(VLOOKUP(A111,[1]FALTANTES!$A:$AD,30,FALSE),"-") -> -1 | K111: ENTREGUE 18 PEÇAS NOS DANFES 41761 & 41762 EM 09/02-METALFISA | L111: =SUM(M111:AS111) -> 1 | M111: =SUMIFS(METALFISA!$E:$E,METALFISA!$A:$A,'Faltantes Fevereiro- Metalfisa'!M$3,METALFISA!$B:$B,'Faltantes Fevereiro- Metalfisa'!$A111) -> 0 | N111: =SUMIFS(METALFISA!$E:$E,METALFISA!$A:$A,'Faltantes Fevereiro- Metalfisa'!N$3,METALFISA!$B:$B,'Faltantes Fevereiro- Metalfisa'!$A111) -> 0 | O111: =SUMIFS(METALFISA!$E:$E,METALFISA!$A:$A,'Faltantes Fevereiro- Metalfisa'!O$3,METALFISA!$B:$B,'Faltantes Fevereiro- Metalfisa'!$A111) -> 0 | P111: =SUMIFS(METALFISA!$E:$E,METALFISA!$A:$A,'Faltantes Fevereiro- Metalfisa'!P$3,METALFISA!$B:$B,'Faltantes Fevereiro- Metalfisa'!$A111) -> 0 | Q111: =SUMIFS(METALFISA!$E:$E,METALFISA!$A:$A,'Faltantes Fevereiro- Metalfisa'!Q$3,METALFISA!$B:$B,'Faltantes Fevereiro- Metalfisa'!$A111) -> 0 | R111: =SUMIFS(METALFISA!$E:$E,METALFISA!$A:$A,'Faltantes Fevereiro- Metalfisa'!R$3,METALFISA!$B:$B,'Faltantes Fevereiro- Metalfisa'!$A111) -> 0 | S111: =SUMIFS(METALFISA!$E:$E,METALFISA!$A:$A,'Faltantes Fevereiro- Metalfisa'!S$3,METALFISA!$B:$B,'Faltantes Fevereiro- Metalfisa'!$A111) -> 0 | T111: =SUMIFS(METALFISA!$E:$E,METALFISA!$A:$A,'Faltantes Fevereiro- Metalfisa'!T$3,METALFISA!$B:$B,'Faltantes Fevereiro- Metalfisa'!$A111) -> 0 | ... AP111: =SUMIFS(METALFISA!$E:$E,METALFISA!$A:$A,'Faltantes Fevereiro- Metalfisa'!AP$3,METALFISA!$B:$B,'Faltantes Fevereiro- Metalfisa'!$A111) -> 0 | AR111: =SUMIFS(METALFISA!$E:$E,METALFISA!$A:$A,'Faltantes Fevereiro- Metalfisa'!AR$3,METALFISA!$B:$B,'Faltantes Fevereiro- Metalfisa'!$A111) -> 0 | AS111: =SUMIFS(METALFISA!$E:$E,METALFISA!$A:$A,'Faltantes Fevereiro- Metalfisa'!AS$3,METALFISA!$B:$B,'Faltantes Fevereiro- Metalfisa'!$A111) -> 0 | AU111: 0 | AV111: 0 | AW111: 0 | AX111: 0 | AY111: 1 | AZ111: 1 | BA111: 0 | BB111: 0 | BC111: 0 | BD111: 0 | BE111: 0 | BF111: 0 | BG111: 0 | BH111: 0 | BI111: 0 | BJ111: 0 | BK111: 0 | BL111: 0 | BM111: 0 | BN111: 0 | BO111: 0 | BP111: 0 | BQ111: 0 | BR111: 0 | BS111: 0 | BT111: 0 | BU111: 0 | BV111: 0 | BW111: 0 | BX111: 0 | BY111: 0 | BZ111: 0 | CA111: 0 | CB111: 0 | CC111: 0 | CD111: 0 | CE111: 0 | CF111: 0 | CG111: 0 | CH111: 0 | CI111: 0 | CJ111: 0 | CK111: 0 | CL111: 0
A112: 21.23.02267 | B112: APOIO DA SOLENOIDE / AA_9998_06 | C112: 0 | D112: 0 | E112: 0 | F112: 0 | G112: 2 | H112: =IFERROR(VLOOKUP(A112,[1]FALTANTES!$A:$AB,28,FALSE),"-") -> 0 | I112: =IFERROR(VLOOKUP(A112,[1]FALTANTES!$A:$AC,29,FALSE),"-") -> 1 | J112: =IFERROR(VLOOKUP(A112,[1]FALTANTES!$A:$AD,30,FALSE),"-") -> -1 | K112: 0 | L112: =SUM(M112:AS112) -> 3 | M112: =SUMIFS(METALFISA!$E:$E,METALFISA!$A:$A,'Faltantes Fevereiro- Metalfisa'!M$3,METALFISA!$B:$B,'Faltantes Fevereiro- Metalfisa'!$A112) -> 0 | N112: =SUMIFS(METALFISA!$E:$E,METALFISA!$A:$A,'Faltantes Fevereiro- Metalfisa'!N$3,METALFISA!$B:$B,'Faltantes Fevereiro- Metalfisa'!$A112) -> 0 | O112: =SUMIFS(METALFISA!$E:$E,METALFISA!$A:$A,'Faltantes Fevereiro- Metalfisa'!O$3,METALFISA!$B:$B,'Faltantes Fevereiro- Metalfisa'!$A112) -> 0 | P112: =SUMIFS(METALFISA!$E:$E,METALFISA!$A:$A,'Faltantes Fevereiro- Metalfisa'!P$3,METALFISA!$B:$B,'Faltantes Fevereiro- Metalfisa'!$A112) -> 0 | Q112: =SUMIFS(METALFISA!$E:$E,METALFISA!$A:$A,'Faltantes Fevereiro- Metalfisa'!Q$3,METALFISA!$B:$B,'Faltantes Fevereiro- Metalfisa'!$A112) -> 0 | R112: =SUMIFS(METALFISA!$E:$E,METALFISA!$A:$A,'Faltantes Fevereiro- Metalfisa'!R$3,METALFISA!$B:$B,'Faltantes Fevereiro- Metalfisa'!$A112) -> 0 | S112: =SUMIFS(METALFISA!$E:$E,METALFISA!$A:$A,'Faltantes Fevereiro- Metalfisa'!S$3,METALFISA!$B:$B,'Faltantes Fevereiro- Metalfisa'!$A112) -> 0 | T112: =SUMIFS(METALFISA!$E:$E,METALFISA!$A:$A,'Faltantes Fevereiro- Metalfisa'!T$3,METALFISA!$B:$B,'Faltantes Fevereiro- Metalfisa'!$A112) -> 0 | ... AP112: =SUMIFS(METALFISA!$E:$E,METALFISA!$A:$A,'Faltantes Fevereiro- Metalfisa'!AP$3,METALFISA!$B:$B,'Faltantes Fevereiro- Metalfisa'!$A112) -> 0 | AR112: =SUMIFS(METALFISA!$E:$E,METALFISA!$A:$A,'Faltantes Fevereiro- Metalfisa'!AR$3,METALFISA!$B:$B,'Faltantes Fevereiro- Metalfisa'!$A112) -> 0 | AS112: =SUMIFS(METALFISA!$E:$E,METALFISA!$A:$A,'Faltantes Fevereiro- Metalfisa'!AS$3,METALFISA!$B:$B,'Faltantes Fevereiro- Metalfisa'!$A112) -> 0 | AU112: 0 | AV112: 0 | AW112: 0 | AX112: 0 | AY112: 0 | AZ112: 1 | BA112: 0 | BB112: 0 | BC112: 0 | BD112: 0 | BE112: 0 | BF112: 0 | BG112: 0 | BH112: 0 | BI112: 0 | BJ112: 0 | BK112: 0 | BL112: 0 | BM112: 0 | BN112: 0 | BO112: 0 | BP112: 0 | BQ112: 0 | BR112: 0 | BS112: 0 | BT112: 0 | BU112: 0 | BV112: 0 | BW112: 0 | BX112: 0 | BY112: 0 | BZ112: 0 | CA112: 0 | CB112: 0 | CC112: 0 | CD112: 0 | CE112: 0 | CF112: 0 | CG112: 0 | CH112: 0 | CI112: 0 | CJ112: 0 | CK112: 0 | CL112: 0
